Workbook
Name ACMS: OFFSET('(Fill In) SIAO'!$DC$12,0,0,COUNTA('(Fill In) SIAO'!$DC$12:$DC$335))
Name ATMS: OFFSET('[1](Fill In) SIAO'!$DA$12,0,0,COUNTA('[1](Fill In) SIAO'!$DA$12:$DA$377))
Name Conducts: OFFSET(#REF!,0,0,COUNTA(#REF!),1)
Name EndDate: OFFSET('(Fill In) SIAO'!$G$12,0,0,COUNTA('(Fill In) SIAO'!$G$12:$G$335))
Name Heli: OFFSET('(Fill In) SIAO'!$DG$12,0,0,COUNTA('(Fill In) SIAO'!$DG$12:$DG$335))
Name HLT: OFFSET('(Fill In) SIAO'!$DE$12,0,0,COUNTA('(Fill In) SIAO'!$DE$12:$DE$335))
Name MMR: OFFSET('(Fill In) SIAO'!$DB$12,0,0,COUNTA('(Fill In) SIAO'!$DB$12:$DB$335))
Name Optics: OFFSET('(Fill In) SIAO'!#REF!,0,0,COUNTA('(Fill In) SIAO'!#REF!))
Name PANTES: OFFSET('(Fill In) SIAO'!$DF$12,0,0,COUNTA('(Fill In) SIAO'!$DF$12:$DF$335))
Name POL: OFFSET('(Fill In) SIAO'!$DJ$12,0,0,COUNTA('(Fill In) SIAO'!$DJ$12:$DJ$335))
Name Signals: OFFSET('(Fill In) SIAO'!#REF!,0,0,COUNTA('(Fill In) SIAO'!#REF!))
Name SMARTO: OFFSET(#REF!,0,0,COUNTA(#REF!),COUNTA(#REF!))
Name StartDate: OFFSET('(Fill In) SIAO'!$E$12,0,0,COUNTA('(Fill In) SIAO'!$E$12:$E$335))
Name UO: OFFSET('[1](Fill In) SIAO'!$DB$12,0,0,COUNTA('[1](Fill In) SIAO'!$DB$12:$DB$377))
Name UOCE: OFFSET('(Fill In) SIAO'!$DD$12,0,0,COUNTA('(Fill In) SIAO'!$DD$12:$DD$335))

Sheet (Fill In) SIAO
B1: SMARTO Indenting Assistant @ OCS | L1: Click to expand ->
B2: Wing | C2: TWG | W2: =COLUMN()-$J$8 -> 43
B3: Strength | W3: =COLUMN()*5-210 -> -95
B4: No. of Platoons | W4: =COLUMN()*5-209 -> -94
B5: No. of Sections | W5: =6+$J$7 -> -22
B6: No. of Groups | W6: =COLUMN()+29 -> 52
B7: Month | I7: No. of Columns added since 090118 | J7: -28 | L7: <- Please fill in | W7: =52*5-217 -> 43
J8: =8+J7 -> -20 | W8: =COLUMN()*5-72 -> 43 | BF8: =-9+$J$7 -> -37 | CE8: -7 | CP8: -6
B9: S/N | C9: Exercise | D9: FILL IN THE COLUMNS BELOW | L9: General Details | M9: Medic | Q9: Medic | R9: Ammo | V9: Ammo | BN9: Ammo | BO9: Ration (RDA) | BP9: Ration | BQ9: Transport | DA9: Transport | DQ9: Others
R10: General | V10: General | W10: Conventional Arms | AR10: Conventional Arms | AS10: Demolition | BI10: Demolition | BJ10: Others | BM10: Others | BQ10: Start: Date / Timing | BR10: End: Date / Timing | BS10: LUV (HQ) | BT10: MB290 (HQ) | BU10: LUV (PLC) | BV10: SOUV | BW10: 5-Ton | BX10: GP Car | BY10: Other Vehicles (Boats, Trailers, F550) | BZ10: TO | CA10: Reporting Venue | CB10: Destination Venue | CC10: Parkover | CD10: Remarks | CE10: Indent ID | CF10: Military Transport | CG10: Date/Timing | CI10: Venue | CK10: 20 - seater | CL10: 40 - seater | CM10: 15 Ton Lorry | CN10: 1 way / 2 way / Disposal | CO10: POC + Contact Number | CP10: Indent ID | CQ10: Civilian Transport | CR10: RPL | CV10: Fast Craft | CZ10: Sea Transport | DB10: Stores | DK10: Stores | DL10: ICCT Instructors | DM10: SOC Key | DN10: Link Bridge Key | DO10: M1 Gate Key | DP10: Others
D11: Remarks (E.g. Tying in with Another Exercise?) | E11: Start Date | F11: Start Time | G11: End Date | H11: End Time | I11: Conducting Officer | J11: Contact No. | K11: Area to Book | M11: Start: Date / Timing | N11: End: Date / Timing | O11: Reporting Venue | P11: No. Required | R11: Collection Date/Timing | S11: Return Date/Timing | T11: Ammo Collection Base | U11: Remarks (E.g no. of rounds for demonstration) | W11: 5.56MM BLANK | X11: 5.56MM LIVE | Y11: 5.56MM TRACER | Z11: 7.62MM BLANK | AA11: 7.62MM LIVE | AB11: 40MM TP | AC11: 40MM ILLUM | AD11: 40MM HEDP | AE11: MATADOR SUBCAL | AF11: MATADOR HEAT | AG11: 5.56MM MMR RED | AH11: 5.56MM MMR BLUE | AI11: CTG SIG 16MM GREEN | AJ11: CTG SIG 16MM ILLUM | AK11: CTG SIG 16MM RED | AL11: FLARE SURFACE TRIPWIRE MK2 | AM11: DIRECTIONAL FRAGMENTATION CHARGE M18A1 (CLAYMORE) | AN11: SIM THUNFLASH NON-ELEC | AO11: THUNDERFLASH, ELECTRIC | AP11: GRENADE HAND SMOKE SCREENING N452 | AQ11: DEMO KIT BANGALORE TORPEDO NO 21 | AS11: BOOSTER DEMOLITION CHARGE, PETN, NO. 1 | AT11: CHARGE DEMOLITION TNT FLAKES | AU11: CHGE DEMO BLK NO 3 0.5KG | AV11: CORD DETONATING, PETN (6000-7000 M/SEC) | AW11: DEMO KIT PROJECTED LINE CHGE | AX11: DETONATOR,NON-ELEC NO.8 | AY11: DETONATOR ELECTRIC,NO. 8 | AZ11: FDD NO.41, W/STAINLESS STL, INNER TUBE | BA11: FUSE BLASTING, INSTANTANEOUS,30 M/SEC | BB11: FUSE BLASTING TIME SAFETY, 15.24M/EA | BC11: IGN TIME BLAST FUSE NE | BD11: MATCH SAFETY 1.9 INCH | BE11: PLASTIC EXPLOSIVE, PETN, 125GM IN M2A1 BOX | BF11: RKT HAND FIRED 38MM ILLUM 400M | BG11: RKT HAND FIRED PARACHUTE SIGNAL RED | BH11: SIMULATOR FLASH ARTILLERY, TNT | BJ11: PELLET RIOT CONTROL AGENT SMOKE CS | BK11: SIGNAL, SMOKE: MARINE MK9 | BL11: CARTRIDGE 9MM LUGER, SINTOX, BALL - 8G | CG11: From | CH11: To | CI11: From | CJ11: To | CR11: Date / Time | CS11: From | CT11: To | CU11: Vehicle Details (with Authorised Troops) | CV11: Date / Time | CW11: From | CX11: To | CY11: Vehicle Details (with Authorised Troops) | DB11: MMR WCK + PPE | DC11: ACMS | DD11: UOCE | DE11: Heartlanders Tools | DF11: PANTES | DG11: Heli Belts | DH11: ALFRE | DI11: iPETS | DJ11: POL
B12: EG | C12: DEMO LIVE FIRING | D12: Route March (8km) | E12: 43377 | F12: 800 | G12: 43378 | H12: 1000 | I12: LTA Tan Ah Kow | J12: 91234567 | K12: =VLOOKUP($C12,SMARTO,COLUMN()-9) -> #REF! | M12: =IF(Q12="Y",TEXT($E12,"ddmmyy")&" "&TEXT($F12,"0000"),"-") -> #REF! | N12: =IF(Q12="Y",TEXT($G12,"ddmmyy")&" "&TEXT($H12,"0000"),"-") -> #REF! | O12: =IF(VLOOKUP($C12,SMARTO,COLUMN()-$J$8)="-","-",$K12) -> #REF! | P12: =VLOOKUP($C12,SMARTO,COLUMN()-$J$8) -> #REF! | Q12: =VLOOKUP($C12,SMARTO,COLUMN()-$J$8) -> #REF! | R12: =IF($BN12="Y",TEXT(E12,"ddmmyy")&" 0600","-") -> #REF! | S12: =IF($BN12="Y",TEXT(G12,"ddmmyy")&" 2359","-") -> #REF! | T12: =VLOOKUP($C12,SMARTO,COLUMN()-$J$8) -> #REF! | U12: =VLOOKUP($C12,SMARTO,COLUMN()-$J$8) -> #REF! | V12: =IF(SUM(R12:U12)>0,"Y","") -> #REF! | W12: =IFERROR(VLOOKUP($C12,SMARTO,COLUMN()*5-72)*$C$3+VLOOKUP($C12,SMARTO,COLUMN()*5-71)*$C$6+VLOOKUP($C12,SMARTO,COLUMN()*5-70)*$C$5+VLOOKUP($C12,SMARTO,COLUMN()*5-69)*$C$4+VLOOKUP($C12,SMARTO,COLUMN()*5-68),"-") -> - | X12: =IFERROR(VLOOKUP($C12,SMARTO,COLUMN()*5-72)*$C$3+VLOOKUP($C12,SMARTO,COLUMN()*5-71)*$C$6+VLOOKUP($C12,SMARTO,COLUMN()*5-70)*$C$5+VLOOKUP($C12,SMARTO,COLUMN()*5-69)*$C$4+VLOOKUP($C12,SMARTO,COLUMN()*5-68),"-") -> - | Y12: =IFERROR(VLOOKUP($C12,SMARTO,COLUMN()*5-72)*$C$3+VLOOKUP($C12,SMARTO,COLUMN()*5-71)*$C$6+VLOOKUP($C12,SMARTO,COLUMN()*5-70)*$C$5+VLOOKUP($C12,SMARTO,COLUMN()*5-69)*$C$4+VLOOKUP($C12,SMARTO,COLUMN()*5-68),"-") -> - | Z12: =IFERROR(VLOOKUP($C12,SMARTO,COLUMN()*5-72)*$C$3+VLOOKUP($C12,SMARTO,COLUMN()*5-71)*$C$6+VLOOKUP($C12,SMARTO,COLUMN()*5-70)*$C$5+VLOOKUP($C12,SMARTO,COLUMN()*5-69)*$C$4+VLOOKUP($C12,SMARTO,COLUMN()*5-68),"-") -> - | AA12: =IFERROR(VLOOKUP($C12,SMARTO,COLUMN()*5-72)*$C$3+VLOOKUP($C12,SMARTO,COLUMN()*5-71)*$C$6+VLOOKUP($C12,SMARTO,COLUMN()*5-70)*$C$5+VLOOKUP($C12,SMARTO,COLUMN()*5-69)*$C$4+VLOOKUP($C12,SMARTO,COLUMN()*5-68),"-") -> - | AB12: =IFERROR(VLOOKUP($C12,SMARTO,COLUMN()*5-72)*$C$3+VLOOKUP($C12,SMARTO,COLUMN()*5-71)*$C$6+VLOOKUP($C12,SMARTO,COLUMN()*5-70)*$C$5+VLOOKUP($C12,SMARTO,COLUMN()*5-69)*$C$4+VLOOKUP($C12,SMARTO,COLUMN()*5-68),"-") -> - | AC12: =IFERROR(VLOOKUP($C12,SMARTO,COLUMN()*5-72)*$C$3+VLOOKUP($C12,SMARTO,COLUMN()*5-71)*$C$6+VLOOKUP($C12,SMARTO,COLUMN()*5-70)*$C$5+VLOOKUP($C12,SMARTO,COLUMN()*5-69)*$C$4+VLOOKUP($C12,SMARTO,COLUMN()*5-68),"-") -> - | AD12: =IFERROR(VLOOKUP($C12,SMARTO,COLUMN()*5-72)*$C$3+VLOOKUP($C12,SMARTO,COLUMN()*5-71)*$C$6+VLOOKUP($C12,SMARTO,COLUMN()*5-70)*$C$5+VLOOKUP($C12,SMARTO,COLUMN()*5-69)*$C$4+VLOOKUP($C12,SMARTO,COLUMN()*5-68),"-") -> - | ... AQ12: =IFERROR(VLOOKUP($C12,SMARTO,COLUMN()*5-72)*$C$3+VLOOKUP($C12,SMARTO,COLUMN()*5-71)*$C$6+VLOOKUP($C12,SMARTO,COLUMN()*5-70)*$C$5+VLOOKUP($C12,SMARTO,COLUMN()*5-69)*$C$4+VLOOKUP($C12,SMARTO,COLUMN()*5-68),"-") -> - | AR12: =IF(SUM(W12:AQ12)>0,"Y","") | AS12: =IFERROR(VLOOKUP($C12,SMARTO,COLUMN()-$J$8+84),"-") -> - | AT12: =IFERROR(VLOOKUP($C12,SMARTO,COLUMN()-$J$8+84),"-") -> - | AU12: =IFERROR(VLOOKUP($C12,SMARTO,COLUMN()-$J$8+84),"-") -> - | AV12: =IFERROR(VLOOKUP($C12,SMARTO,COLUMN()-$J$8+84),"-") -> - | AW12: =IFERROR(VLOOKUP($C12,SMARTO,COLUMN()-$J$8+84),"-") -> - | AX12: =IFERROR(VLOOKUP($C12,SMARTO,COLUMN()-$J$8+84),"-") -> - | AY12: =IFERROR(VLOOKUP($C12,SMARTO,COLUMN()-$J$8+84),"-") -> - | AZ12: =IFERROR(VLOOKUP($C12,SMARTO,COLUMN()-$J$8+84),"-") -> - | ... BE12: =IFERROR(VLOOKUP($C12,SMARTO,COLUMN()-$J$8+84),"-") -> - | BF12: =IFERROR(VLOOKUP($C12,SMARTO,COLUMN()-$J$8+84)*$C$5,"-") -> - | BG12: =IFERROR(VLOOKUP($C12,SMARTO,COLUMN()-$J$8+84),"-") -> - | BH12: =VLOOKUP($C12,SMARTO,COLUMN()-$J$8+84) -> #REF! | BI12: =IF(SUM(AS12:BH12)>0,"Y","") -> #REF! | BJ12: =IFERROR(VLOOKUP($C12,SMARTO,COLUMN()-$J$8+84),"-") -> - | BK12: =IFERROR(VLOOKUP($C12,SMARTO,COLUMN()-$J$8+84),"-") -> - | BL12: =IFERROR(VLOOKUP($C12,SMARTO,COLUMN()-$J$8+84)*$C$3,"-") -> - | BM12: =IF(SUM(BJ12:BL12)>0,"Y","") | BN12: =VLOOKUP($C12,SMARTO,COLUMN()-$J$8+84) -> #REF! | BO12: =VLOOKUP($C12,SMARTO,COLUMN()-$J$8+84) -> #REF! | BP12: =VLOOKUP($C12,SMARTO,COLUMN()-$J$8+84) -> #REF! | BQ12: =IF(SUM($BU12:$BZ12)>0,TEXT($E12,"ddmmyy")&" "&TEXT($F12,"0000"),"-") -> #REF! | BR12: =IF(SUM($BU12:$BZ12)>0,TEXT($G12,"ddmmyy")&" "&TEXT($H12,"0000"),"-") -> #REF! | BU12: =VLOOKUP($C12,SMARTO,COLUMN()-$J$8+84) -> #REF! | BV12: =VLOOKUP($C12,SMARTO,COLUMN()-$J$8+84) -> #REF! | BW12: =VLOOKUP($C12,SMARTO,COLUMN()-$J$8+84) -> #REF! | BX12: =VLOOKUP($C12,SMARTO,COLUMN()-$J$8+84) -> #REF! | BY12: =VLOOKUP($C12,SMARTO,COLUMN()-$J$8+84) -> #REF! | BZ12: =IF(SUM(BU12:BW12)=0,"-",SUM(BU12:BW12)) -> #REF! | CA12: =VLOOKUP($C12,SMARTO,COLUMN()-$J$8+84) -> #REF! | CB12: =IF(VLOOKUP($C12,SMARTO,COLUMN()-$J$8+84)="-","-",$K12) -> #REF! | CC12: =IF(VLOOKUP($C12,SMARTO,COLUMN()-$J$8+84)="-","-",E12-1) -> #REF! | CD12: =VLOOKUP($C12,SMARTO,COLUMN()-$J$8+84) -> #REF! | CE12: =VLOOKUP($C12,SMARTO,COLUMN()-$J$8+84) -> #REF! | CF12: =IF(SUM(BQ12:CD12)>0,"Y","") -> #REF! | CG12: =IF(SUM($CK12:$CM12)=0,"-",TEXT($E12,"ddmmyy")&" "&TEXT($F12,"0000")) -> #REF! | CH12: =IF(SUM($CK12:$CM12)=0,"-",TEXT($G12,"ddmmyy")&" "&TEXT($H12,"0000")) -> #REF! | CI12: =VLOOKUP($C12,SMARTO,COLUMN()-$J$8+84) -> #REF! | CJ12: =IF(VLOOKUP($C12,SMARTO,COLUMN()-$J$8+84)="-","-",$K12) -> #REF! | CK12: =VLOOKUP($C12,SMARTO,COLUMN()-$J$8+84) -> #REF! | CL12: =VLOOKUP($C12,SMARTO,COLUMN()-$J$8+84) -> #REF! | CM12: =VLOOKUP($C12,SMARTO,COLUMN()-$J$8+84) -> #REF! | CN12: =VLOOKUP($C12,SMARTO,COLUMN()-$J$8+84) -> #REF! | CO12: =IF(SUM($CG12:$CN12)=0,"-",I12&" "&J12) -> #REF! | CP12: =VLOOKUP($C12,SMARTO,COLUMN()-$J$8+84) -> #REF! | CQ12: =IF(SUM(CG12:CO12)>0,"Y","") -> #REF! | CR12: =IF(VLOOKUP($C12,SMARTO,COLUMN()-$J$8+84)="-","-",TEXT($E12,"ddmmyy")&" "&TEXT($F12,"0000")&" / "&TEXT($G12,"ddmmyy")&" "&TEXT($H12,"0000")) -> #REF! | CS12: =VLOOKUP($C12,SMARTO,COLUMN()-$J$8+84) -> #REF! | CT12: =VLOOKUP($C12,SMARTO,COLUMN()-$J$8+84) -> #REF! | CU12: =VLOOKUP($C12,SMARTO,COLUMN()-$J$8+84) -> #REF! | CV12: =IF(VLOOKUP($C12,SMARTO,COLUMN()-$J$8+84)="-","-",TEXT($E12,"ddmmyy")&" "&TEXT($F12,"0000")&" / "&TEXT($G12,"ddmmyy")&" "&TEXT($H12,"0000")) -> #REF! | CW12: =VLOOKUP($C12,SMARTO,COLUMN()-$J$8+84) -> #REF! | CX12: =VLOOKUP($C12,SMARTO,COLUMN()-$J$8+84) -> #REF! | CY12: =IF(VLOOKUP($C12,SMARTO,COLUMN()-$J$8+84)="-","-",$C$3+20) -> #REF! | CZ12: =IF(CX12="-","","Y") -> #REF! | DA12: =VLOOKUP($C12,SMARTO,COLUMN()-$J$8+84) -> #REF! | DB12: =VLOOKUP($C12,SMARTO,COLUMN()-$J$8+84) -> #REF! | DC12: =VLOOKUP($C12,SMARTO,COLUMN()-$J$8+84) -> #REF! | DD12: =VLOOKUP($C12,SMARTO,COLUMN()-$J$8+84) -> #REF! | DE12: =VLOOKUP($C12,SMARTO,COLUMN()-$J$8+84) -> #REF! | DF12: =VLOOKUP($C12,SMARTO,COLUMN()-$J$8+84) -> #REF! | DG12: =VLOOKUP($C12,SMARTO,COLUMN()-$J$8+84) -> #REF! | DH12: =VLOOKUP($C12,SMARTO,COLUMN()-$J$8+84) -> #REF! | ... DJ12: =VLOOKUP($C12,SMARTO,COLUMN()-$J$8+84) -> #REF! | DK12: {=IF(OR(DB12:DJ12="Y"),"Y","")} -> #REF! | DL12: =VLOOKUP($C12,SMARTO,COLUMN()-$J$8+84) -> #REF! | DM12: =VLOOKUP($C12,SMARTO,COLUMN()-$J$8+84) -> #REF! | DN12: =VLOOKUP($C12,SMARTO,COLUMN()-$J$8+84) -> #REF! | DO12: =VLOOKUP($C12,SMARTO,COLUMN()-$J$8+84) -> #REF! | DP12: =VLOOKUP($C12,SMARTO,COLUMN()-$J$8+84) -> #REF! | DQ12: =VLOOKUP($C12,SMARTO,COLUMN()-$J$8+84) -> #REF!

Sheet (Fill In) CE & Signals 
A1: 46266 | AK1: 46296 | BU1: 46327
C2: {=IF((C$48>=$AN$11:$AN$74)*(C$48<=$AO$11:$AO$74),$AM$11:$AM$74,"")} | D2: {=IF((D$48>=$AN$11:$AN$74)*(D$48<=$AO$11:$AO$74),$AM$11:$AM$74,"")} -> 46265 | E2: {=IF((E$48>=$AN$11:$AN$74)*(E$48<=$AO$11:$AO$74),$AM$11:$AM$74,"")} -> 46265 | F2: {=IF((F$48>=$AN$11:$AN$74)*(F$48<=$AO$11:$AO$74),$AM$11:$AM$74,"")} | G2: {=IF((G$48>=$AN$11:$AN$74)*(G$48<=$AO$11:$AO$74),$AM$11:$AM$74,"")} | H2: {=IF((H$48>=$AN$11:$AN$74)*(H$48<=$AO$11:$AO$74),$AM$11:$AM$74,"")} | I2: {=IF((I$48>=$AN$11:$AN$74)*(I$48<=$AO$11:$AO$74),$AM$11:$AM$74,"")} | J2: {=IF((J$48>=$AN$11:$AN$74)*(J$48<=$AO$11:$AO$74),$AM$11:$AM$74,"")} | ... AI2: {=IF((AI$48>=$AN$11:$AN$74)*(AI$48<=$AO$11:$AO$74),$AM$11:$AM$74,"")} | AM2: {=IF((AM$48>=$AN$11:$AN$74)*(AM$48<=$AO$11:$AO$74),$AM$11:$AM$74,"")} | AN2: {=IF((AN$48>=$AN$11:$AN$74)*(AN$48<=$AO$11:$AO$74),$AM$11:$AM$74,"")} -> 46265 | AO2: {=IF((AO$48>=$AN$11:$AN$74)*(AO$48<=$AO$11:$AO$74),$AM$11:$AM$74,"")} -> 46265 | AP2: {=IF((AP$48>=$AN$11:$AN$74)*(AP$48<=$AO$11:$AO$74),$AM$11:$AM$74,"")} | AQ2: {=IF((AQ$48>=$AN$11:$AN$74)*(AQ$48<=$AO$11:$AO$74),$AM$11:$AM$74,"")} | AR2: {=IF((AR$48>=$AN$11:$AN$74)*(AR$48<=$AO$11:$AO$74),$AM$11:$AM$74,"")} | AS2: {=IF((AS$48>=$AN$11:$AN$74)*(AS$48<=$AO$11:$AO$74),$AM$11:$AM$74,"")} | AT2: {=IF((AT$48>=$AN$11:$AN$74)*(AT$48<=$AO$11:$AO$74),$AM$11:$AM$74,"")} | ... BS2: {=IF((BS$48>=$AN$11:$AN$74)*(BS$48<=$AO$11:$AO$74),$AM$11:$AM$74,"")} | BW2: {=IF((BW$48>=$AN$11:$AN$74)*(BW$48<=$AO$11:$AO$74),$AM$11:$AM$74,"")} | BX2: {=IF((BX$48>=$AN$11:$AN$74)*(BX$48<=$AO$11:$AO$74),$AM$11:$AM$74,"")} -> 46265 | BY2: {=IF((BY$48>=$AN$11:$AN$74)*(BY$48<=$AO$11:$AO$74),$AM$11:$AM$74,"")} -> 46265 | BZ2: {=IF((BZ$48>=$AN$11:$AN$74)*(BZ$48<=$AO$11:$AO$74),$AM$11:$AM$74,"")} | CA2: {=IF((CA$48>=$AN$11:$AN$74)*(CA$48<=$AO$11:$AO$74),$AM$11:$AM$74,"")} | CB2: {=IF((CB$48>=$AN$11:$AN$74)*(CB$48<=$AO$11:$AO$74),$AM$11:$AM$74,"")} | CC2: {=IF((CC$48>=$AN$11:$AN$74)*(CC$48<=$AO$11:$AO$74),$AM$11:$AM$74,"")} | CD2: {=IF((CD$48>=$AN$11:$AN$74)*(CD$48<=$AO$11:$AO$74),$AM$11:$AM$74,"")} | ... DC2: {=IF((DC$48>=$AN$11:$AN$74)*(DC$48<=$AO$11:$AO$74),$AM$11:$AM$74,"")}
A10: Signals | AK10: Signals | BU10: Signals
B11: Default | C11: =EOMONTH($A$1,-1) -> 46265 | D11: =C11+1 -> 46266 | E11: =D11+1 -> 46267 | F11: =E11+1 -> 46268 | G11: =F11+1 -> 46269 | H11: =G11+1 -> 46270 | I11: =H11+1 -> 46271 | J11: =I11+1 -> 46272 | K11: =J11+1 -> 46273 | ... AI11: =AH11+1 -> 46297 | AL11: Default | AM11: =EOMONTH($A$1,-1) -> 46265 | AN11: =AM11+1 -> 46266 | AO11: =AN11+1 -> 46267 | AP11: =AO11+1 -> 46268 | AQ11: =AP11+1 -> 46269 | AR11: =AQ11+1 -> 46270 | AS11: =AR11+1 -> 46271 | AT11: =AS11+1 -> 46272 | AU11: =AT11+1 -> 46273 | ... BS11: =BR11+1 -> 46297 | BV11: Default | BW11: =EOMONTH($A$1,-1) -> 46265 | BX11: =BW11+1 -> 46266 | BY11: =BX11+1 -> 46267 | BZ11: =BY11+1 -> 46268 | CA11: =BZ11+1 -> 46269 | CB11: =CA11+1 -> 46270 | CC11: =CB11+1 -> 46271 | CD11: =CC11+1 -> 46272 | CE11: =CD11+1 -> 46273 | ... DC11: =DB11+1 -> 46297
A12: PRC 650 | AK12: PRC 650 | BU12: PRC 650
A13: PRC 940 | AK13: PRC 940 | BU13: PRC 940
A14: DIPOLE | AK14: DIPOLE | BU14: DIPOLE
A15: AM78 | AK15: AM78 | BU15: AM78
A16: VRC 947 | AK16: VRC 947 | BU16: VRC 947
A17: TA427 | AK17: TA427 | BU17: TA427
A18: SB22 | AK18: SB22 | BU18: SB22
A19: RL11 + D10 | AK19: RL11 + D10 | BU19: RL11 + D10
A20: WALKIE TALKIE | AK20: WALKIE TALKIE | BU20: WALKIE TALKIE
A21: MCN | AK21: MCN | BU21: MCN
A31: Optics | AK31: Optics | BU31: Optics
B32: Default | C32: =EOMONTH($A$1,-1) -> 46265 | D32: =C32+1 -> 46266 | E32: =D32+1 -> 46267 | F32: =E32+1 -> 46268 | G32: =F32+1 -> 46269 | H32: =G32+1 -> 46270 | I32: =H32+1 -> 46271 | J32: =I32+1 -> 46272 | K32: =J32+1 -> 46273 | ... AI32: =AH32+1 -> 46297 | AL32: Default | AM32: =EOMONTH($A$1,-1) -> 46265 | AN32: =AM32+1 -> 46266 | AO32: =AN32+1 -> 46267 | AP32: =AO32+1 -> 46268 | AQ32: =AP32+1 -> 46269 | AR32: =AQ32+1 -> 46270 | AS32: =AR32+1 -> 46271 | AT32: =AS32+1 -> 46272 | AU32: =AT32+1 -> 46273 | ... BS32: =BR32+1 -> 46297 | BV32: Default | BW32: =EOMONTH($A$1,-1) -> 46265 | BX32: =BW32+1 -> 46266 | BY32: =BX32+1 -> 46267 | BZ32: =BY32+1 -> 46268 | CA32: =BZ32+1 -> 46269 | CB32: =CA32+1 -> 46270 | CC32: =CB32+1 -> 46271 | CD32: =CC32+1 -> 46272 | CE32: =CD32+1 -> 46273 | ... DC32: =DB32+1 -> 46297
A33: BINOCULAR: 8 X 30, SWAROVSKI | AK33: BINOCULAR: 8 X 30, SWAROVSKI | BU33: BINOCULAR: 8 X 30, SWAROVSKI
A34: BINOCULAR: 8 X MAGN, 30 MM | AK34: BINOCULAR: 8 X MAGN, 30 MM | BU34: BINOCULAR: 8 X MAGN, 30 MM
A35: READER, MAP, BETALIGHT | AK35: READER, MAP, BETALIGHT | BU35: READER, MAP, BETALIGHT
A36: COMPASS MAGNETIC | AK36: COMPASS MAGNETIC | BU36: COMPASS MAGNETIC
A37: LASER AIMING DEVICE, VISIBLE | AK37: LASER AIMING DEVICE, VISIBLE | BU37: LASER AIMING DEVICE, VISIBLE
A38: LASER AIMING DEVICE, IR | AK38: LASER AIMING DEVICE, IR | BU38: LASER AIMING DEVICE, IR
A39: LMG BORELIGHT | AK39: LMG BORELIGHT | BU39: LMG BORELIGHT
A40: XTREK GPS | AK40: XTREK GPS | BU40: XTREK GPS
A41: IN-REACH GPS | AK41: IN-REACH GPS | BU41: IN-REACH GPS
A42: NVG | AK42: NVG | BU42: NVG
A43: UTWS | AK43: UTWS | BU43: UTWS
A44: NIGHTHAWK | AK44: NIGHTHAWK | BU44: NIGHTHAWK
... A47: ACMS | AK47: ACMS | BU47: ACMS
B48: Default | C48: =EOMONTH($A$1,-1) -> 46265 | D48: =C48+1 -> 46266 | E48: =D48+1 -> 46267 | F48: =E48+1 -> 46268 | G48: =F48+1 -> 46269 | H48: =G48+1 -> 46270 | I48: =H48+1 -> 46271 | J48: =I48+1 -> 46272 | K48: =J48+1 -> 46273 | ... AI48: =AH48+1 -> 46297 | AL48: Default | AM48: =EOMONTH($A$1,-1) -> 46265 | AN48: =AM48+1 -> 46266 | AO48: =AN48+1 -> 46267 | AP48: =AO48+1 -> 46268 | AQ48: =AP48+1 -> 46269 | AR48: =AQ48+1 -> 46270 | AS48: =AR48+1 -> 46271 | AT48: =AS48+1 -> 46272 | AU48: =AT48+1 -> 46273 | ... BS48: =BR48+1 -> 46297 | BV48: Default | BW48: =EOMONTH($A$1,-1) -> 46265 | BX48: =BW48+1 -> 46266 | BY48: =BX48+1 -> 46267 | BZ48: =BY48+1 -> 46268 | CA48: =BZ48+1 -> 46269 | CB48: =CA48+1 -> 46270 | CC48: =CB48+1 -> 46271 | CD48: =CC48+1 -> 46272 | CE48: =CD48+1 -> 46273 | ... DC48: =DB48+1 -> 46297
A49: Basic Fighting System | B49: 12 | C49: {=IF(OR((C$48>=$AS$11:$AS$74)*(C$48<=$AT$11:$AT$74)>0),$B49,"")} | D49: {=IF(OR((D$48>=$AS$11:$AS$74)*(D$48<=$AT$11:$AT$74)>0),$B49,"")} | E49: {=IF(OR((E$48>=$AS$11:$AS$74)*(E$48<=$AT$11:$AT$74)>0),$B49,"")} | F49: {=IF(OR((F$48>=$AS$11:$AS$74)*(F$48<=$AT$11:$AT$74)>0),$B49,"")} | G49: {=IF(OR((G$48>=$AS$11:$AS$74)*(G$48<=$AT$11:$AT$74)>0),$B49,"")} | H49: {=IF(OR((H$48>=$AS$11:$AS$74)*(H$48<=$AT$11:$AT$74)>0),$B49,"")} | I49: {=IF(OR((I$48>=$AS$11:$AS$74)*(I$48<=$AT$11:$AT$74)>0),$B49,"")} | J49: {=IF(OR((J$48>=$AS$11:$AS$74)*(J$48<=$AT$11:$AT$74)>0),$B49,"")} | ... AI49: {=IF(OR((AI$48>=$AS$11:$AS$74)*(AI$48<=$AT$11:$AT$74)>0),$B49,"")} | AK49: Basic Fighting System | AL49: 12 | AM49: {=IF(OR((AM$48>=$AS$11:$AS$74)*(AM$48<=$AT$11:$AT$74)>0),$B49,"")} | AN49: {=IF(OR((AN$48>=$AS$11:$AS$74)*(AN$48<=$AT$11:$AT$74)>0),$B49,"")} | AO49: {=IF(OR((AO$48>=$AS$11:$AS$74)*(AO$48<=$AT$11:$AT$74)>0),$B49,"")} | AP49: {=IF(OR((AP$48>=$AS$11:$AS$74)*(AP$48<=$AT$11:$AT$74)>0),$B49,"")} | AQ49: {=IF(OR((AQ$48>=$AS$11:$AS$74)*(AQ$48<=$AT$11:$AT$74)>0),$B49,"")} | AR49: {=IF(OR((AR$48>=$AS$11:$AS$74)*(AR$48<=$AT$11:$AT$74)>0),$B49,"")} | AS49: {=IF(OR((AS$48>=$AS$11:$AS$74)*(AS$48<=$AT$11:$AT$74)>0),$B49,"")} | AT49: {=IF(OR((AT$48>=$AS$11:$AS$74)*(AT$48<=$AT$11:$AT$74)>0),$B49,"")} | ... BS49: {=IF(OR((BS$48>=$AS$11:$AS$74)*(BS$48<=$AT$11:$AT$74)>0),$B49,"")} | BU49: Basic Fighting System | BV49: 12 | BW49: {=IF(OR((BW$48>=$AS$11:$AS$74)*(BW$48<=$AT$11:$AT$74)>0),$B49,"")} | BX49: {=IF(OR((BX$48>=$AS$11:$AS$74)*(BX$48<=$AT$11:$AT$74)>0),$B49,"")} | BY49: {=IF(OR((BY$48>=$AS$11:$AS$74)*(BY$48<=$AT$11:$AT$74)>0),$B49,"")} | BZ49: {=IF(OR((BZ$48>=$AS$11:$AS$74)*(BZ$48<=$AT$11:$AT$74)>0),$B49,"")} | CA49: {=IF(OR((CA$48>=$AS$11:$AS$74)*(CA$48<=$AT$11:$AT$74)>0),$B49,"")} | CB49: {=IF(OR((CB$48>=$AS$11:$AS$74)*(CB$48<=$AT$11:$AT$74)>0),$B49,"")} | CC49: {=IF(OR((CC$48>=$AS$11:$AS$74)*(CC$48<=$AT$11:$AT$74)>0),$B49,"")} | CD49: {=IF(OR((CD$48>=$AS$11:$AS$74)*(CD$48<=$AT$11:$AT$74)>0),$B49,"")} | ... DC49: {=IF(OR((DC$48>=$AS$11:$AS$74)*(DC$48<=$AT$11:$AT$74)>0),$B49,"")}
A50: Commander Enhancement Addon | B50: 12 | C50: {=IF(OR((C$48>=$AS$11:$AS$74)*(C$48<=$AT$11:$AT$74)>0),$B50,"")} | D50: {=IF(OR((D$48>=$AS$11:$AS$74)*(D$48<=$AT$11:$AT$74)>0),$B50,"")} | E50: {=IF(OR((E$48>=$AS$11:$AS$74)*(E$48<=$AT$11:$AT$74)>0),$B50,"")} | F50: {=IF(OR((F$48>=$AS$11:$AS$74)*(F$48<=$AT$11:$AT$74)>0),$B50,"")} | G50: {=IF(OR((G$48>=$AS$11:$AS$74)*(G$48<=$AT$11:$AT$74)>0),$B50,"")} | H50: {=IF(OR((H$48>=$AS$11:$AS$74)*(H$48<=$AT$11:$AT$74)>0),$B50,"")} | I50: {=IF(OR((I$48>=$AS$11:$AS$74)*(I$48<=$AT$11:$AT$74)>0),$B50,"")} | J50: {=IF(OR((J$48>=$AS$11:$AS$74)*(J$48<=$AT$11:$AT$74)>0),$B50,"")} | ... AI50: {=IF(OR((AI$48>=$AS$11:$AS$74)*(AI$48<=$AT$11:$AT$74)>0),$B50,"")} | AK50: Commander Enhancement Addon | AL50: 12 | AM50: {=IF(OR((AM$48>=$AS$11:$AS$74)*(AM$48<=$AT$11:$AT$74)>0),$B50,"")} | AN50: {=IF(OR((AN$48>=$AS$11:$AS$74)*(AN$48<=$AT$11:$AT$74)>0),$B50,"")} | AO50: {=IF(OR((AO$48>=$AS$11:$AS$74)*(AO$48<=$AT$11:$AT$74)>0),$B50,"")} | AP50: {=IF(OR((AP$48>=$AS$11:$AS$74)*(AP$48<=$AT$11:$AT$74)>0),$B50,"")} | AQ50: {=IF(OR((AQ$48>=$AS$11:$AS$74)*(AQ$48<=$AT$11:$AT$74)>0),$B50,"")} | AR50: {=IF(OR((AR$48>=$AS$11:$AS$74)*(AR$48<=$AT$11:$AT$74)>0),$B50,"")} | AS50: {=IF(OR((AS$48>=$AS$11:$AS$74)*(AS$48<=$AT$11:$AT$74)>0),$B50,"")} | AT50: {=IF(OR((AT$48>=$AS$11:$AS$74)*(AT$48<=$AT$11:$AT$74)>0),$B50,"")} | ... BS50: {=IF(OR((BS$48>=$AS$11:$AS$74)*(BS$48<=$AT$11:$AT$74)>0),$B50,"")} | BU50: Commander Enhancement Addon | BV50: 12 | BW50: {=IF(OR((BW$48>=$AS$11:$AS$74)*(BW$48<=$AT$11:$AT$74)>0),$B50,"")} | BX50: {=IF(OR((BX$48>=$AS$11:$AS$74)*(BX$48<=$AT$11:$AT$74)>0),$B50,"")} | BY50: {=IF(OR((BY$48>=$AS$11:$AS$74)*(BY$48<=$AT$11:$AT$74)>0),$B50,"")} | BZ50: {=IF(OR((BZ$48>=$AS$11:$AS$74)*(BZ$48<=$AT$11:$AT$74)>0),$B50,"")} | CA50: {=IF(OR((CA$48>=$AS$11:$AS$74)*(CA$48<=$AT$11:$AT$74)>0),$B50,"")} | CB50: {=IF(OR((CB$48>=$AS$11:$AS$74)*(CB$48<=$AT$11:$AT$74)>0),$B50,"")} | CC50: {=IF(OR((CC$48>=$AS$11:$AS$74)*(CC$48<=$AT$11:$AT$74)>0),$B50,"")} | CD50: {=IF(OR((CD$48>=$AS$11:$AS$74)*(CD$48<=$AT$11:$AT$74)>0),$B50,"")} | ... DC50: {=IF(OR((DC$48>=$AS$11:$AS$74)*(DC$48<=$AT$11:$AT$74)>0),$B50,"")}
A51: SAR21 MMS | B51: 12 | C51: {=IF(OR((C$48>=$AS$11:$AS$74)*(C$48<=$AT$11:$AT$74)>0),$B51,"")} | D51: {=IF(OR((D$48>=$AS$11:$AS$74)*(D$48<=$AT$11:$AT$74)>0),$B51,"")} | E51: {=IF(OR((E$48>=$AS$11:$AS$74)*(E$48<=$AT$11:$AT$74)>0),$B51,"")} | F51: {=IF(OR((F$48>=$AS$11:$AS$74)*(F$48<=$AT$11:$AT$74)>0),$B51,"")} | G51: {=IF(OR((G$48>=$AS$11:$AS$74)*(G$48<=$AT$11:$AT$74)>0),$B51,"")} | H51: {=IF(OR((H$48>=$AS$11:$AS$74)*(H$48<=$AT$11:$AT$74)>0),$B51,"")} | I51: {=IF(OR((I$48>=$AS$11:$AS$74)*(I$48<=$AT$11:$AT$74)>0),$B51,"")} | J51: {=IF(OR((J$48>=$AS$11:$AS$74)*(J$48<=$AT$11:$AT$74)>0),$B51,"")} | ... AI51: {=IF(OR((AI$48>=$AS$11:$AS$74)*(AI$48<=$AT$11:$AT$74)>0),$B51,"")} | AK51: SAR21 MMS | AL51: 12 | AM51: {=IF(OR((AM$48>=$AS$11:$AS$74)*(AM$48<=$AT$11:$AT$74)>0),$B51,"")} | AN51: {=IF(OR((AN$48>=$AS$11:$AS$74)*(AN$48<=$AT$11:$AT$74)>0),$B51,"")} | AO51: {=IF(OR((AO$48>=$AS$11:$AS$74)*(AO$48<=$AT$11:$AT$74)>0),$B51,"")} | AP51: {=IF(OR((AP$48>=$AS$11:$AS$74)*(AP$48<=$AT$11:$AT$74)>0),$B51,"")} | AQ51: {=IF(OR((AQ$48>=$AS$11:$AS$74)*(AQ$48<=$AT$11:$AT$74)>0),$B51,"")} | AR51: {=IF(OR((AR$48>=$AS$11:$AS$74)*(AR$48<=$AT$11:$AT$74)>0),$B51,"")} | AS51: {=IF(OR((AS$48>=$AS$11:$AS$74)*(AS$48<=$AT$11:$AT$74)>0),$B51,"")} | AT51: {=IF(OR((AT$48>=$AS$11:$AS$74)*(AT$48<=$AT$11:$AT$74)>0),$B51,"")} | ... BS51: {=IF(OR((BS$48>=$AS$11:$AS$74)*(BS$48<=$AT$11:$AT$74)>0),$B51,"")} | BU51: SAR21 MMS | BV51: 12 | BW51: {=IF(OR((BW$48>=$AS$11:$AS$74)*(BW$48<=$AT$11:$AT$74)>0),$B51,"")} | BX51: {=IF(OR((BX$48>=$AS$11:$AS$74)*(BX$48<=$AT$11:$AT$74)>0),$B51,"")} | BY51: {=IF(OR((BY$48>=$AS$11:$AS$74)*(BY$48<=$AT$11:$AT$74)>0),$B51,"")} | BZ51: {=IF(OR((BZ$48>=$AS$11:$AS$74)*(BZ$48<=$AT$11:$AT$74)>0),$B51,"")} | CA51: {=IF(OR((CA$48>=$AS$11:$AS$74)*(CA$48<=$AT$11:$AT$74)>0),$B51,"")} | CB51: {=IF(OR((CB$48>=$AS$11:$AS$74)*(CB$48<=$AT$11:$AT$74)>0),$B51,"")} | CC51: {=IF(OR((CC$48>=$AS$11:$AS$74)*(CC$48<=$AT$11:$AT$74)>0),$B51,"")} | CD51: {=IF(OR((CD$48>=$AS$11:$AS$74)*(CD$48<=$AT$11:$AT$74)>0),$B51,"")} | ... DC51: {=IF(OR((DC$48>=$AS$11:$AS$74)*(DC$48<=$AT$11:$AT$74)>0),$B51,"")}
A52: UMPC | B52: 12 | C52: {=IF(OR((C$48>=$AS$11:$AS$74)*(C$48<=$AT$11:$AT$74)>0),$B52,"")} | D52: {=IF(OR((D$48>=$AS$11:$AS$74)*(D$48<=$AT$11:$AT$74)>0),$B52,"")} | E52: {=IF(OR((E$48>=$AS$11:$AS$74)*(E$48<=$AT$11:$AT$74)>0),$B52,"")} | F52: {=IF(OR((F$48>=$AS$11:$AS$74)*(F$48<=$AT$11:$AT$74)>0),$B52,"")} | G52: {=IF(OR((G$48>=$AS$11:$AS$74)*(G$48<=$AT$11:$AT$74)>0),$B52,"")} | H52: {=IF(OR((H$48>=$AS$11:$AS$74)*(H$48<=$AT$11:$AT$74)>0),$B52,"")} | I52: {=IF(OR((I$48>=$AS$11:$AS$74)*(I$48<=$AT$11:$AT$74)>0),$B52,"")} | J52: {=IF(OR((J$48>=$AS$11:$AS$74)*(J$48<=$AT$11:$AT$74)>0),$B52,"")} | ... AI52: {=IF(OR((AI$48>=$AS$11:$AS$74)*(AI$48<=$AT$11:$AT$74)>0),$B52,"")} | AK52: UMPC | AL52: 12 | AM52: {=IF(OR((AM$48>=$AS$11:$AS$74)*(AM$48<=$AT$11:$AT$74)>0),$B52,"")} | AN52: {=IF(OR((AN$48>=$AS$11:$AS$74)*(AN$48<=$AT$11:$AT$74)>0),$B52,"")} | AO52: {=IF(OR((AO$48>=$AS$11:$AS$74)*(AO$48<=$AT$11:$AT$74)>0),$B52,"")} | AP52: {=IF(OR((AP$48>=$AS$11:$AS$74)*(AP$48<=$AT$11:$AT$74)>0),$B52,"")} | AQ52: {=IF(OR((AQ$48>=$AS$11:$AS$74)*(AQ$48<=$AT$11:$AT$74)>0),$B52,"")} | AR52: {=IF(OR((AR$48>=$AS$11:$AS$74)*(AR$48<=$AT$11:$AT$74)>0),$B52,"")} | AS52: {=IF(OR((AS$48>=$AS$11:$AS$74)*(AS$48<=$AT$11:$AT$74)>0),$B52,"")} | AT52: {=IF(OR((AT$48>=$AS$11:$AS$74)*(AT$48<=$AT$11:$AT$74)>0),$B52,"")} | ... BS52: {=IF(OR((BS$48>=$AS$11:$AS$74)*(BS$48<=$AT$11:$AT$74)>0),$B52,"")} | BU52: UMPC | BV52: 12 | BW52: {=IF(OR((BW$48>=$AS$11:$AS$74)*(BW$48<=$AT$11:$AT$74)>0),$B52,"")} | BX52: {=IF(OR((BX$48>=$AS$11:$AS$74)*(BX$48<=$AT$11:$AT$74)>0),$B52,"")} | BY52: {=IF(OR((BY$48>=$AS$11:$AS$74)*(BY$48<=$AT$11:$AT$74)>0),$B52,"")} | BZ52: {=IF(OR((BZ$48>=$AS$11:$AS$74)*(BZ$48<=$AT$11:$AT$74)>0),$B52,"")} | CA52: {=IF(OR((CA$48>=$AS$11:$AS$74)*(CA$48<=$AT$11:$AT$74)>0),$B52,"")} | CB52: {=IF(OR((CB$48>=$AS$11:$AS$74)*(CB$48<=$AT$11:$AT$74)>0),$B52,"")} | CC52: {=IF(OR((CC$48>=$AS$11:$AS$74)*(CC$48<=$AT$11:$AT$74)>0),$B52,"")} | CD52: {=IF(OR((CD$48>=$AS$11:$AS$74)*(CD$48<=$AT$11:$AT$74)>0),$B52,"")} | ... DC52: {=IF(OR((DC$48>=$AS$11:$AS$74)*(DC$48<=$AT$11:$AT$74)>0),$B52,"")}
A53: IMS/HHPC | B53: 4 | C53: {=IF(OR((C$48>=$AS$11:$AS$74)*(C$48<=$AT$11:$AT$74)>0),$B53,"")} | D53: {=IF(OR((D$48>=$AS$11:$AS$74)*(D$48<=$AT$11:$AT$74)>0),$B53,"")} | E53: {=IF(OR((E$48>=$AS$11:$AS$74)*(E$48<=$AT$11:$AT$74)>0),$B53,"")} | F53: {=IF(OR((F$48>=$AS$11:$AS$74)*(F$48<=$AT$11:$AT$74)>0),$B53,"")} | G53: {=IF(OR((G$48>=$AS$11:$AS$74)*(G$48<=$AT$11:$AT$74)>0),$B53,"")} | H53: {=IF(OR((H$48>=$AS$11:$AS$74)*(H$48<=$AT$11:$AT$74)>0),$B53,"")} | I53: {=IF(OR((I$48>=$AS$11:$AS$74)*(I$48<=$AT$11:$AT$74)>0),$B53,"")} | J53: {=IF(OR((J$48>=$AS$11:$AS$74)*(J$48<=$AT$11:$AT$74)>0),$B53,"")} | ... AI53: {=IF(OR((AI$48>=$AS$11:$AS$74)*(AI$48<=$AT$11:$AT$74)>0),$B53,"")} | AK53: IMS/HHPC | AL53: 4 | AM53: {=IF(OR((AM$48>=$AS$11:$AS$74)*(AM$48<=$AT$11:$AT$74)>0),$B53,"")} | AN53: {=IF(OR((AN$48>=$AS$11:$AS$74)*(AN$48<=$AT$11:$AT$74)>0),$B53,"")} | AO53: {=IF(OR((AO$48>=$AS$11:$AS$74)*(AO$48<=$AT$11:$AT$74)>0),$B53,"")} | AP53: {=IF(OR((AP$48>=$AS$11:$AS$74)*(AP$48<=$AT$11:$AT$74)>0),$B53,"")} | AQ53: {=IF(OR((AQ$48>=$AS$11:$AS$74)*(AQ$48<=$AT$11:$AT$74)>0),$B53,"")} | AR53: {=IF(OR((AR$48>=$AS$11:$AS$74)*(AR$48<=$AT$11:$AT$74)>0),$B53,"")} | AS53: {=IF(OR((AS$48>=$AS$11:$AS$74)*(AS$48<=$AT$11:$AT$74)>0),$B53,"")} | AT53: {=IF(OR((AT$48>=$AS$11:$AS$74)*(AT$48<=$AT$11:$AT$74)>0),$B53,"")} | ... BS53: {=IF(OR((BS$48>=$AS$11:$AS$74)*(BS$48<=$AT$11:$AT$74)>0),$B53,"")} | BU53: IMS/HHPC | BV53: 4 | BW53: {=IF(OR((BW$48>=$AS$11:$AS$74)*(BW$48<=$AT$11:$AT$74)>0),$B53,"")} | BX53: {=IF(OR((BX$48>=$AS$11:$AS$74)*(BX$48<=$AT$11:$AT$74)>0),$B53,"")} | BY53: {=IF(OR((BY$48>=$AS$11:$AS$74)*(BY$48<=$AT$11:$AT$74)>0),$B53,"")} | BZ53: {=IF(OR((BZ$48>=$AS$11:$AS$74)*(BZ$48<=$AT$11:$AT$74)>0),$B53,"")} | CA53: {=IF(OR((CA$48>=$AS$11:$AS$74)*(CA$48<=$AT$11:$AT$74)>0),$B53,"")} | CB53: {=IF(OR((CB$48>=$AS$11:$AS$74)*(CB$48<=$AT$11:$AT$74)>0),$B53,"")} | CC53: {=IF(OR((CC$48>=$AS$11:$AS$74)*(CC$48<=$AT$11:$AT$74)>0),$B53,"")} | CD53: {=IF(OR((CD$48>=$AS$11:$AS$74)*(CD$48<=$AT$11:$AT$74)>0),$B53,"")} | ... DC53: {=IF(OR((DC$48>=$AS$11:$AS$74)*(DC$48<=$AT$11:$AT$74)>0),$B53,"")}
A54: HHPC JUNCTION BOX BATTERY | B54: 4 | C54: {=IF(OR((C$48>=$AS$11:$AS$74)*(C$48<=$AT$11:$AT$74)>0),$B54,"")} | D54: {=IF(OR((D$48>=$AS$11:$AS$74)*(D$48<=$AT$11:$AT$74)>0),$B54,"")} | E54: {=IF(OR((E$48>=$AS$11:$AS$74)*(E$48<=$AT$11:$AT$74)>0),$B54,"")} | F54: {=IF(OR((F$48>=$AS$11:$AS$74)*(F$48<=$AT$11:$AT$74)>0),$B54,"")} | G54: {=IF(OR((G$48>=$AS$11:$AS$74)*(G$48<=$AT$11:$AT$74)>0),$B54,"")} | H54: {=IF(OR((H$48>=$AS$11:$AS$74)*(H$48<=$AT$11:$AT$74)>0),$B54,"")} | I54: {=IF(OR((I$48>=$AS$11:$AS$74)*(I$48<=$AT$11:$AT$74)>0),$B54,"")} | J54: {=IF(OR((J$48>=$AS$11:$AS$74)*(J$48<=$AT$11:$AT$74)>0),$B54,"")} | ... AI54: {=IF(OR((AI$48>=$AS$11:$AS$74)*(AI$48<=$AT$11:$AT$74)>0),$B54,"")} | AK54: HHPC JUNCTION BOX BATTERY | AL54: 4 | AM54: {=IF(OR((AM$48>=$AS$11:$AS$74)*(AM$48<=$AT$11:$AT$74)>0),$B54,"")} | AN54: {=IF(OR((AN$48>=$AS$11:$AS$74)*(AN$48<=$AT$11:$AT$74)>0),$B54,"")} | AO54: {=IF(OR((AO$48>=$AS$11:$AS$74)*(AO$48<=$AT$11:$AT$74)>0),$B54,"")} | AP54: {=IF(OR((AP$48>=$AS$11:$AS$74)*(AP$48<=$AT$11:$AT$74)>0),$B54,"")} | AQ54: {=IF(OR((AQ$48>=$AS$11:$AS$74)*(AQ$48<=$AT$11:$AT$74)>0),$B54,"")} | AR54: {=IF(OR((AR$48>=$AS$11:$AS$74)*(AR$48<=$AT$11:$AT$74)>0),$B54,"")} | AS54: {=IF(OR((AS$48>=$AS$11:$AS$74)*(AS$48<=$AT$11:$AT$74)>0),$B54,"")} | AT54: {=IF(OR((AT$48>=$AS$11:$AS$74)*(AT$48<=$AT$11:$AT$74)>0),$B54,"")} | ... BS54: {=IF(OR((BS$48>=$AS$11:$AS$74)*(BS$48<=$AT$11:$AT$74)>0),$B54,"")} | BU54: HHPC JUNCTION BOX BATTERY | BV54: 4 | BW54: {=IF(OR((BW$48>=$AS$11:$AS$74)*(BW$48<=$AT$11:$AT$74)>0),$B54,"")} | BX54: {=IF(OR((BX$48>=$AS$11:$AS$74)*(BX$48<=$AT$11:$AT$74)>0),$B54,"")} | BY54: {=IF(OR((BY$48>=$AS$11:$AS$74)*(BY$48<=$AT$11:$AT$74)>0),$B54,"")} | BZ54: {=IF(OR((BZ$48>=$AS$11:$AS$74)*(BZ$48<=$AT$11:$AT$74)>0),$B54,"")} | CA54: {=IF(OR((CA$48>=$AS$11:$AS$74)*(CA$48<=$AT$11:$AT$74)>0),$B54,"")} | CB54: {=IF(OR((CB$48>=$AS$11:$AS$74)*(CB$48<=$AT$11:$AT$74)>0),$B54,"")} | CC54: {=IF(OR((CC$48>=$AS$11:$AS$74)*(CC$48<=$AT$11:$AT$74)>0),$B54,"")} | CD54: {=IF(OR((CD$48>=$AS$11:$AS$74)*(CD$48<=$AT$11:$AT$74)>0),$B54,"")} | ... DC54: {=IF(OR((DC$48>=$AS$11:$AS$74)*(DC$48<=$AT$11:$AT$74)>0),$B54,"")}
A55: HHPC BATT | B55: 8 | C55: {=IF(OR((C$48>=$AS$11:$AS$74)*(C$48<=$AT$11:$AT$74)>0),$B55,"")} | D55: {=IF(OR((D$48>=$AS$11:$AS$74)*(D$48<=$AT$11:$AT$74)>0),$B55,"")} | E55: {=IF(OR((E$48>=$AS$11:$AS$74)*(E$48<=$AT$11:$AT$74)>0),$B55,"")} | F55: {=IF(OR((F$48>=$AS$11:$AS$74)*(F$48<=$AT$11:$AT$74)>0),$B55,"")} | G55: {=IF(OR((G$48>=$AS$11:$AS$74)*(G$48<=$AT$11:$AT$74)>0),$B55,"")} | H55: {=IF(OR((H$48>=$AS$11:$AS$74)*(H$48<=$AT$11:$AT$74)>0),$B55,"")} | I55: {=IF(OR((I$48>=$AS$11:$AS$74)*(I$48<=$AT$11:$AT$74)>0),$B55,"")} | J55: {=IF(OR((J$48>=$AS$11:$AS$74)*(J$48<=$AT$11:$AT$74)>0),$B55,"")} | ... AI55: {=IF(OR((AI$48>=$AS$11:$AS$74)*(AI$48<=$AT$11:$AT$74)>0),$B55,"")} | AK55: HHPC BATT | AL55: 8 | AM55: {=IF(OR((AM$48>=$AS$11:$AS$74)*(AM$48<=$AT$11:$AT$74)>0),$B55,"")} | AN55: {=IF(OR((AN$48>=$AS$11:$AS$74)*(AN$48<=$AT$11:$AT$74)>0),$B55,"")} | AO55: {=IF(OR((AO$48>=$AS$11:$AS$74)*(AO$48<=$AT$11:$AT$74)>0),$B55,"")} | AP55: {=IF(OR((AP$48>=$AS$11:$AS$74)*(AP$48<=$AT$11:$AT$74)>0),$B55,"")} | AQ55: {=IF(OR((AQ$48>=$AS$11:$AS$74)*(AQ$48<=$AT$11:$AT$74)>0),$B55,"")} | AR55: {=IF(OR((AR$48>=$AS$11:$AS$74)*(AR$48<=$AT$11:$AT$74)>0),$B55,"")} | AS55: {=IF(OR((AS$48>=$AS$11:$AS$74)*(AS$48<=$AT$11:$AT$74)>0),$B55,"")} | AT55: {=IF(OR((AT$48>=$AS$11:$AS$74)*(AT$48<=$AT$11:$AT$74)>0),$B55,"")} | ... BS55: {=IF(OR((BS$48>=$AS$11:$AS$74)*(BS$48<=$AT$11:$AT$74)>0),$B55,"")} | BU55: HHPC BATT | BV55: 8 | BW55: {=IF(OR((BW$48>=$AS$11:$AS$74)*(BW$48<=$AT$11:$AT$74)>0),$B55,"")} | BX55: {=IF(OR((BX$48>=$AS$11:$AS$74)*(BX$48<=$AT$11:$AT$74)>0),$B55,"")} | BY55: {=IF(OR((BY$48>=$AS$11:$AS$74)*(BY$48<=$AT$11:$AT$74)>0),$B55,"")} | BZ55: {=IF(OR((BZ$48>=$AS$11:$AS$74)*(BZ$48<=$AT$11:$AT$74)>0),$B55,"")} | CA55: {=IF(OR((CA$48>=$AS$11:$AS$74)*(CA$48<=$AT$11:$AT$74)>0),$B55,"")} | CB55: {=IF(OR((CB$48>=$AS$11:$AS$74)*(CB$48<=$AT$11:$AT$74)>0),$B55,"")} | CC55: {=IF(OR((CC$48>=$AS$11:$AS$74)*(CC$48<=$AT$11:$AT$74)>0),$B55,"")} | CD55: {=IF(OR((CD$48>=$AS$11:$AS$74)*(CD$48<=$AT$11:$AT$74)>0),$B55,"")} | ... DC55: {=IF(OR((DC$48>=$AS$11:$AS$74)*(DC$48<=$AT$11:$AT$74)>0),$B55,"")}
A56: UMPC BATT | B56: 24 | C56: {=IF(OR((C$48>=$AS$11:$AS$74)*(C$48<=$AT$11:$AT$74)>0),$B56,"")} | D56: {=IF(OR((D$48>=$AS$11:$AS$74)*(D$48<=$AT$11:$AT$74)>0),$B56,"")} | E56: {=IF(OR((E$48>=$AS$11:$AS$74)*(E$48<=$AT$11:$AT$74)>0),$B56,"")} | F56: {=IF(OR((F$48>=$AS$11:$AS$74)*(F$48<=$AT$11:$AT$74)>0),$B56,"")} | G56: {=IF(OR((G$48>=$AS$11:$AS$74)*(G$48<=$AT$11:$AT$74)>0),$B56,"")} | H56: {=IF(OR((H$48>=$AS$11:$AS$74)*(H$48<=$AT$11:$AT$74)>0),$B56,"")} | I56: {=IF(OR((I$48>=$AS$11:$AS$74)*(I$48<=$AT$11:$AT$74)>0),$B56,"")} | J56: {=IF(OR((J$48>=$AS$11:$AS$74)*(J$48<=$AT$11:$AT$74)>0),$B56,"")} | ... AI56: {=IF(OR((AI$48>=$AS$11:$AS$74)*(AI$48<=$AT$11:$AT$74)>0),$B56,"")} | AK56: UMPC BATT | AL56: 24 | AM56: {=IF(OR((AM$48>=$AS$11:$AS$74)*(AM$48<=$AT$11:$AT$74)>0),$B56,"")} | AN56: {=IF(OR((AN$48>=$AS$11:$AS$74)*(AN$48<=$AT$11:$AT$74)>0),$B56,"")} | AO56: {=IF(OR((AO$48>=$AS$11:$AS$74)*(AO$48<=$AT$11:$AT$74)>0),$B56,"")} | AP56: {=IF(OR((AP$48>=$AS$11:$AS$74)*(AP$48<=$AT$11:$AT$74)>0),$B56,"")} | AQ56: {=IF(OR((AQ$48>=$AS$11:$AS$74)*(AQ$48<=$AT$11:$AT$74)>0),$B56,"")} | AR56: {=IF(OR((AR$48>=$AS$11:$AS$74)*(AR$48<=$AT$11:$AT$74)>0),$B56,"")} | AS56: {=IF(OR((AS$48>=$AS$11:$AS$74)*(AS$48<=$AT$11:$AT$74)>0),$B56,"")} | AT56: {=IF(OR((AT$48>=$AS$11:$AS$74)*(AT$48<=$AT$11:$AT$74)>0),$B56,"")} | ... BS56: {=IF(OR((BS$48>=$AS$11:$AS$74)*(BS$48<=$AT$11:$AT$74)>0),$B56,"")} | BU56: UMPC BATT | BV56: 24 | BW56: {=IF(OR((BW$48>=$AS$11:$AS$74)*(BW$48<=$AT$11:$AT$74)>0),$B56,"")} | BX56: {=IF(OR((BX$48>=$AS$11:$AS$74)*(BX$48<=$AT$11:$AT$74)>0),$B56,"")} | BY56: {=IF(OR((BY$48>=$AS$11:$AS$74)*(BY$48<=$AT$11:$AT$74)>0),$B56,"")} | BZ56: {=IF(OR((BZ$48>=$AS$11:$AS$74)*(BZ$48<=$AT$11:$AT$74)>0),$B56,"")} | CA56: {=IF(OR((CA$48>=$AS$11:$AS$74)*(CA$48<=$AT$11:$AT$74)>0),$B56,"")} | CB56: {=IF(OR((CB$48>=$AS$11:$AS$74)*(CB$48<=$AT$11:$AT$74)>0),$B56,"")} | CC56: {=IF(OR((CC$48>=$AS$11:$AS$74)*(CC$48<=$AT$11:$AT$74)>0),$B56,"")} | CD56: {=IF(OR((CD$48>=$AS$11:$AS$74)*(CD$48<=$AT$11:$AT$74)>0),$B56,"")} | ... DC56: {=IF(OR((DC$48>=$AS$11:$AS$74)*(DC$48<=$AT$11:$AT$74)>0),$B56,"")}
A57: BFS/CEA BATT | B57: 24 | C57: {=IF(OR((C$48>=$AS$11:$AS$74)*(C$48<=$AT$11:$AT$74)>0),$B57,"")} | D57: {=IF(OR((D$48>=$AS$11:$AS$74)*(D$48<=$AT$11:$AT$74)>0),$B57,"")} | E57: {=IF(OR((E$48>=$AS$11:$AS$74)*(E$48<=$AT$11:$AT$74)>0),$B57,"")} | F57: {=IF(OR((F$48>=$AS$11:$AS$74)*(F$48<=$AT$11:$AT$74)>0),$B57,"")} | G57: {=IF(OR((G$48>=$AS$11:$AS$74)*(G$48<=$AT$11:$AT$74)>0),$B57,"")} | H57: {=IF(OR((H$48>=$AS$11:$AS$74)*(H$48<=$AT$11:$AT$74)>0),$B57,"")} | I57: {=IF(OR((I$48>=$AS$11:$AS$74)*(I$48<=$AT$11:$AT$74)>0),$B57,"")} | J57: {=IF(OR((J$48>=$AS$11:$AS$74)*(J$48<=$AT$11:$AT$74)>0),$B57,"")} | ... AI57: {=IF(OR((AI$48>=$AS$11:$AS$74)*(AI$48<=$AT$11:$AT$74)>0),$B57,"")} | AK57: BFS/CEA BATT | AL57: 24 | AM57: {=IF(OR((AM$48>=$AS$11:$AS$74)*(AM$48<=$AT$11:$AT$74)>0),$B57,"")} | AN57: {=IF(OR((AN$48>=$AS$11:$AS$74)*(AN$48<=$AT$11:$AT$74)>0),$B57,"")} | AO57: {=IF(OR((AO$48>=$AS$11:$AS$74)*(AO$48<=$AT$11:$AT$74)>0),$B57,"")} | AP57: {=IF(OR((AP$48>=$AS$11:$AS$74)*(AP$48<=$AT$11:$AT$74)>0),$B57,"")} | AQ57: {=IF(OR((AQ$48>=$AS$11:$AS$74)*(AQ$48<=$AT$11:$AT$74)>0),$B57,"")} | AR57: {=IF(OR((AR$48>=$AS$11:$AS$74)*(AR$48<=$AT$11:$AT$74)>0),$B57,"")} | AS57: {=IF(OR((AS$48>=$AS$11:$AS$74)*(AS$48<=$AT$11:$AT$74)>0),$B57,"")} | AT57: {=IF(OR((AT$48>=$AS$11:$AS$74)*(AT$48<=$AT$11:$AT$74)>0),$B57,"")} | ... BS57: {=IF(OR((BS$48>=$AS$11:$AS$74)*(BS$48<=$AT$11:$AT$74)>0),$B57,"")} | BU57: BFS/CEA BATT | BV57: 24 | BW57: {=IF(OR((BW$48>=$AS$11:$AS$74)*(BW$48<=$AT$11:$AT$74)>0),$B57,"")} | BX57: {=IF(OR((BX$48>=$AS$11:$AS$74)*(BX$48<=$AT$11:$AT$74)>0),$B57,"")} | BY57: {=IF(OR((BY$48>=$AS$11:$AS$74)*(BY$48<=$AT$11:$AT$74)>0),$B57,"")} | BZ57: {=IF(OR((BZ$48>=$AS$11:$AS$74)*(BZ$48<=$AT$11:$AT$74)>0),$B57,"")} | CA57: {=IF(OR((CA$48>=$AS$11:$AS$74)*(CA$48<=$AT$11:$AT$74)>0),$B57,"")} | CB57: {=IF(OR((CB$48>=$AS$11:$AS$74)*(CB$48<=$AT$11:$AT$74)>0),$B57,"")} | CC57: {=IF(OR((CC$48>=$AS$11:$AS$74)*(CC$48<=$AT$11:$AT$74)>0),$B57,"")} | CD57: {=IF(OR((CD$48>=$AS$11:$AS$74)*(CD$48<=$AT$11:$AT$74)>0),$B57,"")} | ... DC57: {=IF(OR((DC$48>=$AS$11:$AS$74)*(DC$48<=$AT$11:$AT$74)>0),$B57,"")}
A59: UOCE | AK59: UOCE | BU59: UOCE
...

Sheet (Fill In) Stores 
A1: 46113
AN2: Signals | AQ2: Optics | AS2: ACMS | AU2: UOCE | AW2: Heartlanders | AY2: PANTES | BA2: Heli | BC2: MMR | BE2: POL
A3: ACMS
B4: Default | C4: =EOMONTH($A$1,-1) -> 46112 | D4: =C4+1 -> 46113 | E4: =D4+1 -> 46114 | F4: =E4+1 -> 46115 | G4: =F4+1 -> 46116 | H4: =G4+1 -> 46117 | I4: =H4+1 -> 46118 | J4: =I4+1 -> 46119 | K4: =J4+1 -> 46120 | ... AI4: =AH4+1 -> 46144
A5: Basic Fighting System | B5: 12 | C5: {=IF(OR((C$4>=$AS$11:$AS$74)*(C$4<=$AT$11:$AT$74)>0),$B5,"")} | D5: {=IF(OR((D$4>=$AS$11:$AS$74)*(D$4<=$AT$11:$AT$74)>0),$B5,"")} | E5: {=IF(OR((E$4>=$AS$11:$AS$74)*(E$4<=$AT$11:$AT$74)>0),$B5,"")} | F5: {=IF(OR((F$4>=$AS$11:$AS$74)*(F$4<=$AT$11:$AT$74)>0),$B5,"")} | G5: {=IF(OR((G$4>=$AS$11:$AS$74)*(G$4<=$AT$11:$AT$74)>0),$B5,"")} | H5: {=IF(OR((H$4>=$AS$11:$AS$74)*(H$4<=$AT$11:$AT$74)>0),$B5,"")} | I5: {=IF(OR((I$4>=$AS$11:$AS$74)*(I$4<=$AT$11:$AT$74)>0),$B5,"")} | J5: {=IF(OR((J$4>=$AS$11:$AS$74)*(J$4<=$AT$11:$AT$74)>0),$B5,"")} | ... AI5: {=IF(OR((AI$4>=$AS$11:$AS$74)*(AI$4<=$AT$11:$AT$74)>0),$B5,"")}
A6: Commander Enhancement Addon | B6: 12 | C6: {=IF(OR((C$4>=$AS$11:$AS$74)*(C$4<=$AT$11:$AT$74)>0),$B6,"")} | D6: {=IF(OR((D$4>=$AS$11:$AS$74)*(D$4<=$AT$11:$AT$74)>0),$B6,"")} | E6: {=IF(OR((E$4>=$AS$11:$AS$74)*(E$4<=$AT$11:$AT$74)>0),$B6,"")} | F6: {=IF(OR((F$4>=$AS$11:$AS$74)*(F$4<=$AT$11:$AT$74)>0),$B6,"")} | G6: {=IF(OR((G$4>=$AS$11:$AS$74)*(G$4<=$AT$11:$AT$74)>0),$B6,"")} | H6: {=IF(OR((H$4>=$AS$11:$AS$74)*(H$4<=$AT$11:$AT$74)>0),$B6,"")} | I6: {=IF(OR((I$4>=$AS$11:$AS$74)*(I$4<=$AT$11:$AT$74)>0),$B6,"")} | J6: {=IF(OR((J$4>=$AS$11:$AS$74)*(J$4<=$AT$11:$AT$74)>0),$B6,"")} | ... AI6: {=IF(OR((AI$4>=$AS$11:$AS$74)*(AI$4<=$AT$11:$AT$74)>0),$B6,"")}
A7: SAR21 MMS | B7: 12 | C7: {=IF(OR((C$4>=$AS$11:$AS$74)*(C$4<=$AT$11:$AT$74)>0),$B7,"")} | D7: {=IF(OR((D$4>=$AS$11:$AS$74)*(D$4<=$AT$11:$AT$74)>0),$B7,"")} | E7: {=IF(OR((E$4>=$AS$11:$AS$74)*(E$4<=$AT$11:$AT$74)>0),$B7,"")} | F7: {=IF(OR((F$4>=$AS$11:$AS$74)*(F$4<=$AT$11:$AT$74)>0),$B7,"")} | G7: {=IF(OR((G$4>=$AS$11:$AS$74)*(G$4<=$AT$11:$AT$74)>0),$B7,"")} | H7: {=IF(OR((H$4>=$AS$11:$AS$74)*(H$4<=$AT$11:$AT$74)>0),$B7,"")} | I7: {=IF(OR((I$4>=$AS$11:$AS$74)*(I$4<=$AT$11:$AT$74)>0),$B7,"")} | J7: {=IF(OR((J$4>=$AS$11:$AS$74)*(J$4<=$AT$11:$AT$74)>0),$B7,"")} | ... AI7: {=IF(OR((AI$4>=$AS$11:$AS$74)*(AI$4<=$AT$11:$AT$74)>0),$B7,"")}
A8: UMPC | B8: 12 | C8: {=IF(OR((C$4>=$AS$11:$AS$74)*(C$4<=$AT$11:$AT$74)>0),$B8,"")} | D8: {=IF(OR((D$4>=$AS$11:$AS$74)*(D$4<=$AT$11:$AT$74)>0),$B8,"")} | E8: {=IF(OR((E$4>=$AS$11:$AS$74)*(E$4<=$AT$11:$AT$74)>0),$B8,"")} | F8: {=IF(OR((F$4>=$AS$11:$AS$74)*(F$4<=$AT$11:$AT$74)>0),$B8,"")} | G8: {=IF(OR((G$4>=$AS$11:$AS$74)*(G$4<=$AT$11:$AT$74)>0),$B8,"")} | H8: {=IF(OR((H$4>=$AS$11:$AS$74)*(H$4<=$AT$11:$AT$74)>0),$B8,"")} | I8: {=IF(OR((I$4>=$AS$11:$AS$74)*(I$4<=$AT$11:$AT$74)>0),$B8,"")} | J8: {=IF(OR((J$4>=$AS$11:$AS$74)*(J$4<=$AT$11:$AT$74)>0),$B8,"")} | ... AI8: {=IF(OR((AI$4>=$AS$11:$AS$74)*(AI$4<=$AT$11:$AT$74)>0),$B8,"")}
A9: IMS/HHPC | B9: 4 | C9: {=IF(OR((C$4>=$AS$11:$AS$74)*(C$4<=$AT$11:$AT$74)>0),$B9,"")} | D9: {=IF(OR((D$4>=$AS$11:$AS$74)*(D$4<=$AT$11:$AT$74)>0),$B9,"")} | E9: {=IF(OR((E$4>=$AS$11:$AS$74)*(E$4<=$AT$11:$AT$74)>0),$B9,"")} | F9: {=IF(OR((F$4>=$AS$11:$AS$74)*(F$4<=$AT$11:$AT$74)>0),$B9,"")} | G9: {=IF(OR((G$4>=$AS$11:$AS$74)*(G$4<=$AT$11:$AT$74)>0),$B9,"")} | H9: {=IF(OR((H$4>=$AS$11:$AS$74)*(H$4<=$AT$11:$AT$74)>0),$B9,"")} | I9: {=IF(OR((I$4>=$AS$11:$AS$74)*(I$4<=$AT$11:$AT$74)>0),$B9,"")} | J9: {=IF(OR((J$4>=$AS$11:$AS$74)*(J$4<=$AT$11:$AT$74)>0),$B9,"")} | ... AI9: {=IF(OR((AI$4>=$AS$11:$AS$74)*(AI$4<=$AT$11:$AT$74)>0),$B9,"")}
A10: HHPC JUNCTION BOX BATTERY | B10: 4 | C10: {=IF(OR((C$4>=$AS$11:$AS$74)*(C$4<=$AT$11:$AT$74)>0),$B10,"")} | D10: {=IF(OR((D$4>=$AS$11:$AS$74)*(D$4<=$AT$11:$AT$74)>0),$B10,"")} | E10: {=IF(OR((E$4>=$AS$11:$AS$74)*(E$4<=$AT$11:$AT$74)>0),$B10,"")} | F10: {=IF(OR((F$4>=$AS$11:$AS$74)*(F$4<=$AT$11:$AT$74)>0),$B10,"")} | G10: {=IF(OR((G$4>=$AS$11:$AS$74)*(G$4<=$AT$11:$AT$74)>0),$B10,"")} | H10: {=IF(OR((H$4>=$AS$11:$AS$74)*(H$4<=$AT$11:$AT$74)>0),$B10,"")} | I10: {=IF(OR((I$4>=$AS$11:$AS$74)*(I$4<=$AT$11:$AT$74)>0),$B10,"")} | J10: {=IF(OR((J$4>=$AS$11:$AS$74)*(J$4<=$AT$11:$AT$74)>0),$B10,"")} | ... AI10: {=IF(OR((AI$4>=$AS$11:$AS$74)*(AI$4<=$AT$11:$AT$74)>0),$B10,"")} | AM10: Conduct | AN10: start | AO10: end | AP10: Conduct | AQ10: start | AR10: end | AS10: start | AT10: end | AU10: start | AV10: end | AW10: start | AX10: end | AY10: start | AZ10: end | BA10: start | BB10: end | BC10: start | BD10: end | BE10: start | BF10: end
A11: HHPC BATT | B11: 8 | C11: {=IF(OR((C$4>=$AS$11:$AS$74)*(C$4<=$AT$11:$AT$74)>0),$B11,"")} | D11: {=IF(OR((D$4>=$AS$11:$AS$74)*(D$4<=$AT$11:$AT$74)>0),$B11,"")} | E11: {=IF(OR((E$4>=$AS$11:$AS$74)*(E$4<=$AT$11:$AT$74)>0),$B11,"")} | F11: {=IF(OR((F$4>=$AS$11:$AS$74)*(F$4<=$AT$11:$AT$74)>0),$B11,"")} | G11: {=IF(OR((G$4>=$AS$11:$AS$74)*(G$4<=$AT$11:$AT$74)>0),$B11,"")} | H11: {=IF(OR((H$4>=$AS$11:$AS$74)*(H$4<=$AT$11:$AT$74)>0),$B11,"")} | I11: {=IF(OR((I$4>=$AS$11:$AS$74)*(I$4<=$AT$11:$AT$74)>0),$B11,"")} | J11: {=IF(OR((J$4>=$AS$11:$AS$74)*(J$4<=$AT$11:$AT$74)>0),$B11,"")} | ... AI11: {=IF(OR((AI$4>=$AS$11:$AS$74)*(AI$4<=$AT$11:$AT$74)>0),$B11,"")} | AK11: Instances | AL11: 1 | AM11: {=IFERROR(OFFSET('[1](Fill In) SIAO'!$A$1,SMALL(IF(Signals="Y",ROW(Signals)),AL11)-1,COLUMN(Conducts)-1),"")} | AN11: {=IFERROR(OFFSET('[1](Fill In) SIAO'!$A$1,SMALL(IF(Signals="Y",ROW(Signals)),AL11)-1,COLUMN(StartDate)-1),"")} | AO11: {=IFERROR(OFFSET('[1](Fill In) SIAO'!$A$1,SMALL(IF(Signals="Y",ROW(Signals)),AL11)-1,COLUMN(EndDate)-1),"")} | AP11: {=IFERROR(OFFSET('[1](Fill In) SIAO'!$A$1,SMALL(IF(Optics="Y",ROW(Optics)),AL11)-1,COLUMN(Conducts)-1),"")} | AQ11: {=IFERROR(OFFSET('[1](Fill In) SIAO'!$A$1,SMALL(IF(Optics="Y",ROW(Optics)),AL11)-1,COLUMN(StartDate)-1),"")} | AR11: {=IFERROR(OFFSET('[1](Fill In) SIAO'!$A$1,SMALL(IF(Optics="Y",ROW(Optics)),AL11)-1,COLUMN(EndDate)-1),"")} | AS11: {=IFERROR(OFFSET('[1](Fill In) SIAO'!$A$1,SMALL(IF(ATMS="Y",ROW(ATMS)),AL11)-1,COLUMN(StartDate)-1),"")} | AT11: {=IFERROR(OFFSET('[1](Fill In) SIAO'!$A$1,SMALL(IF(ATMS="Y",ROW(ATMS)),AL11)-1,COLUMN(EndDate)-1),"")} | AU11: {=IFERROR(OFFSET('[1](Fill In) SIAO'!$A$1,SMALL(IF(UO="Y",ROW(UO)),AL11)-1,COLUMN(StartDate)-1),"")} | AV11: {=IFERROR(OFFSET('[1](Fill In) SIAO'!$A$1,SMALL(IF(UO="Y",ROW(UO)),AL11)-1,COLUMN(EndDate)-1),"")} | AW11: {=IFERROR(OFFSET('[1](Fill In) SIAO'!$A$1,SMALL(IF(HLT="Y",ROW(HLT)),AL11)-1,COLUMN(StartDate)-1),"")} | AX11: {=IFERROR(OFFSET('[1](Fill In) SIAO'!$A$1,SMALL(IF(HLT="Y",ROW(HLT)),AL11)-1,COLUMN(EndDate)-1),"")} | AY11: {=IFERROR(OFFSET('[1](Fill In) SIAO'!$A$1,SMALL(IF(PANTES="Y",ROW(PANTES)),AL11)-1,COLUMN(StartDate)-1),"")} | AZ11: {=IFERROR(OFFSET('[1](Fill In) SIAO'!$A$1,SMALL(IF(PANTES="Y",ROW(PANTES)),AL11)-1,COLUMN(EndDate)-1),"")} | BA11: {=IFERROR(OFFSET('[1](Fill In) SIAO'!$A$1,SMALL(IF(Heli="Y",ROW(Heli)),AL11)-1,COLUMN(StartDate)-1),"")} | BB11: {=IFERROR(OFFSET('[1](Fill In) SIAO'!$A$1,SMALL(IF(Heli="Y",ROW(Heli)),AL11)-1,COLUMN(EndDate)-1),"")} | BC11: {=IFERROR(OFFSET('[1](Fill In) SIAO'!$A$1,SMALL(IF(MMR="Y",ROW(MMR)),AL11)-1,COLUMN(StartDate)-1),"")} | BD11: {=IFERROR(OFFSET('[1](Fill In) SIAO'!$A$1,SMALL(IF(MMR="Y",ROW(MMR)),AL11)-1,COLUMN(EndDate)-1),"")} | BE11: {=IFERROR(OFFSET('[1](Fill In) SIAO'!$A$1,SMALL(IF(POL="Y",ROW(POL)),AL11)-1,COLUMN(StartDate)-1),"")} | BF11: {=IFERROR(OFFSET('[1](Fill In) SIAO'!$A$1,SMALL(IF(POL="Y",ROW(POL)),AL11)-1,COLUMN(EndDate)-1),"")}
A12: UMPC BATT | B12: 24 | C12: {=IF(OR((C$4>=$AS$11:$AS$74)*(C$4<=$AT$11:$AT$74)>0),$B12,"")} | D12: {=IF(OR((D$4>=$AS$11:$AS$74)*(D$4<=$AT$11:$AT$74)>0),$B12,"")} | E12: {=IF(OR((E$4>=$AS$11:$AS$74)*(E$4<=$AT$11:$AT$74)>0),$B12,"")} | F12: {=IF(OR((F$4>=$AS$11:$AS$74)*(F$4<=$AT$11:$AT$74)>0),$B12,"")} | G12: {=IF(OR((G$4>=$AS$11:$AS$74)*(G$4<=$AT$11:$AT$74)>0),$B12,"")} | H12: {=IF(OR((H$4>=$AS$11:$AS$74)*(H$4<=$AT$11:$AT$74)>0),$B12,"")} | I12: {=IF(OR((I$4>=$AS$11:$AS$74)*(I$4<=$AT$11:$AT$74)>0),$B12,"")} | J12: {=IF(OR((J$4>=$AS$11:$AS$74)*(J$4<=$AT$11:$AT$74)>0),$B12,"")} | ... AI12: {=IF(OR((AI$4>=$AS$11:$AS$74)*(AI$4<=$AT$11:$AT$74)>0),$B12,"")} | AL12: 2 | AM12: {=IFERROR(OFFSET('[1](Fill In) SIAO'!$A$1,SMALL(IF(Signals="Y",ROW(Signals)),AL12)-1,COLUMN(Conducts)-1),"")} | AN12: {=IFERROR(OFFSET('[1](Fill In) SIAO'!$A$1,SMALL(IF(Signals="Y",ROW(Signals)),AL12)-1,COLUMN(StartDate)-1),"")} | AO12: {=IFERROR(OFFSET('[1](Fill In) SIAO'!$A$1,SMALL(IF(Signals="Y",ROW(Signals)),AL12)-1,COLUMN(EndDate)-1),"")} | AP12: {=IFERROR(OFFSET('[1](Fill In) SIAO'!$A$1,SMALL(IF(Optics="Y",ROW(Optics)),AL12)-1,COLUMN(Conducts)-1),"")} | AQ12: {=IFERROR(OFFSET('[1](Fill In) SIAO'!$A$1,SMALL(IF(Optics="Y",ROW(Optics)),AL12)-1,COLUMN(StartDate)-1),"")} | AR12: {=IFERROR(OFFSET('[1](Fill In) SIAO'!$A$1,SMALL(IF(Optics="Y",ROW(Optics)),AL12)-1,COLUMN(EndDate)-1),"")} | AS12: {=IFERROR(OFFSET('[1](Fill In) SIAO'!$A$1,SMALL(IF(ATMS="Y",ROW(ATMS)),AL12)-1,COLUMN(StartDate)-1),"")} | AT12: {=IFERROR(OFFSET('[1](Fill In) SIAO'!$A$1,SMALL(IF(ATMS="Y",ROW(ATMS)),AL12)-1,COLUMN(EndDate)-1),"")} | AU12: {=IFERROR(OFFSET('[1](Fill In) SIAO'!$A$1,SMALL(IF(UO="Y",ROW(UO)),AL12)-1,COLUMN(StartDate)-1),"")} | AV12: {=IFERROR(OFFSET('[1](Fill In) SIAO'!$A$1,SMALL(IF(UO="Y",ROW(UO)),AL12)-1,COLUMN(EndDate)-1),"")} | AW12: {=IFERROR(OFFSET('[1](Fill In) SIAO'!$A$1,SMALL(IF(HLT="Y",ROW(HLT)),AL12)-1,COLUMN(StartDate)-1),"")} | AX12: {=IFERROR(OFFSET('[1](Fill In) SIAO'!$A$1,SMALL(IF(HLT="Y",ROW(HLT)),AL12)-1,COLUMN(EndDate)-1),"")} | AY12: {=IFERROR(OFFSET('[1](Fill In) SIAO'!$A$1,SMALL(IF(PANTES="Y",ROW(PANTES)),AL12)-1,COLUMN(StartDate)-1),"")} | AZ12: {=IFERROR(OFFSET('[1](Fill In) SIAO'!$A$1,SMALL(IF(PANTES="Y",ROW(PANTES)),AL12)-1,COLUMN(EndDate)-1),"")} | BA12: {=IFERROR(OFFSET('[1](Fill In) SIAO'!$A$1,SMALL(IF(Heli="Y",ROW(Heli)),AL12)-1,COLUMN(StartDate)-1),"")} | BB12: {=IFERROR(OFFSET('[1](Fill In) SIAO'!$A$1,SMALL(IF(Heli="Y",ROW(Heli)),AL12)-1,COLUMN(EndDate)-1),"")} | BC12: {=IFERROR(OFFSET('[1](Fill In) SIAO'!$A$1,SMALL(IF(MMR="Y",ROW(MMR)),AL12)-1,COLUMN(StartDate)-1),"")} | BD12: {=IFERROR(OFFSET('[1](Fill In) SIAO'!$A$1,SMALL(IF(MMR="Y",ROW(MMR)),AL12)-1,COLUMN(EndDate)-1),"")} | BE12: {=IFERROR(OFFSET('[1](Fill In) SIAO'!$A$1,SMALL(IF(POL="Y",ROW(POL)),AL12)-1,COLUMN(StartDate)-1),"")} | BF12: {=IFERROR(OFFSET('[1](Fill In) SIAO'!$A$1,SMALL(IF(POL="Y",ROW(POL)),AL12)-1,COLUMN(EndDate)-1),"")}
A13: BFS/CEA BATT | B13: 24 | C13: {=IF(OR((C$4>=$AS$11:$AS$74)*(C$4<=$AT$11:$AT$74)>0),$B13,"")} | D13: {=IF(OR((D$4>=$AS$11:$AS$74)*(D$4<=$AT$11:$AT$74)>0),$B13,"")} | E13: {=IF(OR((E$4>=$AS$11:$AS$74)*(E$4<=$AT$11:$AT$74)>0),$B13,"")} | F13: {=IF(OR((F$4>=$AS$11:$AS$74)*(F$4<=$AT$11:$AT$74)>0),$B13,"")} | G13: {=IF(OR((G$4>=$AS$11:$AS$74)*(G$4<=$AT$11:$AT$74)>0),$B13,"")} | H13: {=IF(OR((H$4>=$AS$11:$AS$74)*(H$4<=$AT$11:$AT$74)>0),$B13,"")} | I13: {=IF(OR((I$4>=$AS$11:$AS$74)*(I$4<=$AT$11:$AT$74)>0),$B13,"")} | J13: {=IF(OR((J$4>=$AS$11:$AS$74)*(J$4<=$AT$11:$AT$74)>0),$B13,"")} | ... AI13: {=IF(OR((AI$4>=$AS$11:$AS$74)*(AI$4<=$AT$11:$AT$74)>0),$B13,"")} | AL13: 3 | AM13: {=IFERROR(OFFSET('[1](Fill In) SIAO'!$A$1,SMALL(IF(Signals="Y",ROW(Signals)),AL13)-1,COLUMN(Conducts)-1),"")} | AN13: {=IFERROR(OFFSET('[1](Fill In) SIAO'!$A$1,SMALL(IF(Signals="Y",ROW(Signals)),AL13)-1,COLUMN(StartDate)-1),"")} | AO13: {=IFERROR(OFFSET('[1](Fill In) SIAO'!$A$1,SMALL(IF(Signals="Y",ROW(Signals)),AL13)-1,COLUMN(EndDate)-1),"")} | AP13: {=IFERROR(OFFSET('[1](Fill In) SIAO'!$A$1,SMALL(IF(Optics="Y",ROW(Optics)),AL13)-1,COLUMN(Conducts)-1),"")} | AQ13: {=IFERROR(OFFSET('[1](Fill In) SIAO'!$A$1,SMALL(IF(Optics="Y",ROW(Optics)),AL13)-1,COLUMN(StartDate)-1),"")} | AR13: {=IFERROR(OFFSET('[1](Fill In) SIAO'!$A$1,SMALL(IF(Optics="Y",ROW(Optics)),AL13)-1,COLUMN(EndDate)-1),"")} | AS13: {=IFERROR(OFFSET('[1](Fill In) SIAO'!$A$1,SMALL(IF(ATMS="Y",ROW(ATMS)),AL13)-1,COLUMN(StartDate)-1),"")} | AT13: {=IFERROR(OFFSET('[1](Fill In) SIAO'!$A$1,SMALL(IF(ATMS="Y",ROW(ATMS)),AL13)-1,COLUMN(EndDate)-1),"")} | AU13: {=IFERROR(OFFSET('[1](Fill In) SIAO'!$A$1,SMALL(IF(UO="Y",ROW(UO)),AL13)-1,COLUMN(StartDate)-1),"")} | AV13: {=IFERROR(OFFSET('[1](Fill In) SIAO'!$A$1,SMALL(IF(UO="Y",ROW(UO)),AL13)-1,COLUMN(EndDate)-1),"")} | AW13: {=IFERROR(OFFSET('[1](Fill In) SIAO'!$A$1,SMALL(IF(HLT="Y",ROW(HLT)),AL13)-1,COLUMN(StartDate)-1),"")} | AX13: {=IFERROR(OFFSET('[1](Fill In) SIAO'!$A$1,SMALL(IF(HLT="Y",ROW(HLT)),AL13)-1,COLUMN(EndDate)-1),"")} | AY13: {=IFERROR(OFFSET('[1](Fill In) SIAO'!$A$1,SMALL(IF(PANTES="Y",ROW(PANTES)),AL13)-1,COLUMN(StartDate)-1),"")} | AZ13: {=IFERROR(OFFSET('[1](Fill In) SIAO'!$A$1,SMALL(IF(PANTES="Y",ROW(PANTES)),AL13)-1,COLUMN(EndDate)-1),"")} | BA13: {=IFERROR(OFFSET('[1](Fill In) SIAO'!$A$1,SMALL(IF(Heli="Y",ROW(Heli)),AL13)-1,COLUMN(StartDate)-1),"")} | BB13: {=IFERROR(OFFSET('[1](Fill In) SIAO'!$A$1,SMALL(IF(Heli="Y",ROW(Heli)),AL13)-1,COLUMN(EndDate)-1),"")} | BC13: {=IFERROR(OFFSET('[1](Fill In) SIAO'!$A$1,SMALL(IF(MMR="Y",ROW(MMR)),AL13)-1,COLUMN(StartDate)-1),"")} | BD13: {=IFERROR(OFFSET('[1](Fill In) SIAO'!$A$1,SMALL(IF(MMR="Y",ROW(MMR)),AL13)-1,COLUMN(EndDate)-1),"")} | BE13: {=IFERROR(OFFSET('[1](Fill In) SIAO'!$A$1,SMALL(IF(POL="Y",ROW(POL)),AL13)-1,COLUMN(StartDate)-1),"")} | BF13: {=IFERROR(OFFSET('[1](Fill In) SIAO'!$A$1,SMALL(IF(POL="Y",ROW(POL)),AL13)-1,COLUMN(EndDate)-1),"")}
AL14: 4 | AM14: {=IFERROR(OFFSET('[1](Fill In) SIAO'!$A$1,SMALL(IF(Signals="Y",ROW(Signals)),AL14)-1,COLUMN(Conducts)-1),"")} | AN14: {=IFERROR(OFFSET('[1](Fill In) SIAO'!$A$1,SMALL(IF(Signals="Y",ROW(Signals)),AL14)-1,COLUMN(StartDate)-1),"")} | AO14: {=IFERROR(OFFSET('[1](Fill In) SIAO'!$A$1,SMALL(IF(Signals="Y",ROW(Signals)),AL14)-1,COLUMN(EndDate)-1),"")} | AP14: {=IFERROR(OFFSET('[1](Fill In) SIAO'!$A$1,SMALL(IF(Optics="Y",ROW(Optics)),AL14)-1,COLUMN(Conducts)-1),"")} | AQ14: {=IFERROR(OFFSET('[1](Fill In) SIAO'!$A$1,SMALL(IF(Optics="Y",ROW(Optics)),AL14)-1,COLUMN(StartDate)-1),"")} | AR14: {=IFERROR(OFFSET('[1](Fill In) SIAO'!$A$1,SMALL(IF(Optics="Y",ROW(Optics)),AL14)-1,COLUMN(EndDate)-1),"")} | AS14: {=IFERROR(OFFSET('[1](Fill In) SIAO'!$A$1,SMALL(IF(ATMS="Y",ROW(ATMS)),AL14)-1,COLUMN(StartDate)-1),"")} | AT14: {=IFERROR(OFFSET('[1](Fill In) SIAO'!$A$1,SMALL(IF(ATMS="Y",ROW(ATMS)),AL14)-1,COLUMN(EndDate)-1),"")} | AU14: {=IFERROR(OFFSET('[1](Fill In) SIAO'!$A$1,SMALL(IF(UO="Y",ROW(UO)),AL14)-1,COLUMN(StartDate)-1),"")} | AV14: {=IFERROR(OFFSET('[1](Fill In) SIAO'!$A$1,SMALL(IF(UO="Y",ROW(UO)),AL14)-1,COLUMN(EndDate)-1),"")} | AW14: {=IFERROR(OFFSET('[1](Fill In) SIAO'!$A$1,SMALL(IF(HLT="Y",ROW(HLT)),AL14)-1,COLUMN(StartDate)-1),"")} | AX14: {=IFERROR(OFFSET('[1](Fill In) SIAO'!$A$1,SMALL(IF(HLT="Y",ROW(HLT)),AL14)-1,COLUMN(EndDate)-1),"")} | AY14: {=IFERROR(OFFSET('[1](Fill In) SIAO'!$A$1,SMALL(IF(PANTES="Y",ROW(PANTES)),AL14)-1,COLUMN(StartDate)-1),"")} | AZ14: {=IFERROR(OFFSET('[1](Fill In) SIAO'!$A$1,SMALL(IF(PANTES="Y",ROW(PANTES)),AL14)-1,COLUMN(EndDate)-1),"")} | BA14: {=IFERROR(OFFSET('[1](Fill In) SIAO'!$A$1,SMALL(IF(Heli="Y",ROW(Heli)),AL14)-1,COLUMN(StartDate)-1),"")} | BB14: {=IFERROR(OFFSET('[1](Fill In) SIAO'!$A$1,SMALL(IF(Heli="Y",ROW(Heli)),AL14)-1,COLUMN(EndDate)-1),"")} | BC14: {=IFERROR(OFFSET('[1](Fill In) SIAO'!$A$1,SMALL(IF(MMR="Y",ROW(MMR)),AL14)-1,COLUMN(StartDate)-1),"")} | BD14: {=IFERROR(OFFSET('[1](Fill In) SIAO'!$A$1,SMALL(IF(MMR="Y",ROW(MMR)),AL14)-1,COLUMN(EndDate)-1),"")} | BE14: {=IFERROR(OFFSET('[1](Fill In) SIAO'!$A$1,SMALL(IF(POL="Y",ROW(POL)),AL14)-1,COLUMN(StartDate)-1),"")} | BF14: {=IFERROR(OFFSET('[1](Fill In) SIAO'!$A$1,SMALL(IF(POL="Y",ROW(POL)),AL14)-1,COLUMN(EndDate)-1),"")}
A15: UOCE | AL15: 5 | AM15: {=IFERROR(OFFSET('[1](Fill In) SIAO'!$A$1,SMALL(IF(Signals="Y",ROW(Signals)),AL15)-1,COLUMN(Conducts)-1),"")} | AN15: {=IFERROR(OFFSET('[1](Fill In) SIAO'!$A$1,SMALL(IF(Signals="Y",ROW(Signals)),AL15)-1,COLUMN(StartDate)-1),"")} | AO15: {=IFERROR(OFFSET('[1](Fill In) SIAO'!$A$1,SMALL(IF(Signals="Y",ROW(Signals)),AL15)-1,COLUMN(EndDate)-1),"")} | AP15: {=IFERROR(OFFSET('[1](Fill In) SIAO'!$A$1,SMALL(IF(Optics="Y",ROW(Optics)),AL15)-1,COLUMN(Conducts)-1),"")} | AQ15: {=IFERROR(OFFSET('[1](Fill In) SIAO'!$A$1,SMALL(IF(Optics="Y",ROW(Optics)),AL15)-1,COLUMN(StartDate)-1),"")} | AR15: {=IFERROR(OFFSET('[1](Fill In) SIAO'!$A$1,SMALL(IF(Optics="Y",ROW(Optics)),AL15)-1,COLUMN(EndDate)-1),"")} | AS15: {=IFERROR(OFFSET('[1](Fill In) SIAO'!$A$1,SMALL(IF(ATMS="Y",ROW(ATMS)),AL15)-1,COLUMN(StartDate)-1),"")} | AT15: {=IFERROR(OFFSET('[1](Fill In) SIAO'!$A$1,SMALL(IF(ATMS="Y",ROW(ATMS)),AL15)-1,COLUMN(EndDate)-1),"")} | AU15: {=IFERROR(OFFSET('[1](Fill In) SIAO'!$A$1,SMALL(IF(UO="Y",ROW(UO)),AL15)-1,COLUMN(StartDate)-1),"")} | AV15: {=IFERROR(OFFSET('[1](Fill In) SIAO'!$A$1,SMALL(IF(UO="Y",ROW(UO)),AL15)-1,COLUMN(EndDate)-1),"")} | AW15: {=IFERROR(OFFSET('[1](Fill In) SIAO'!$A$1,SMALL(IF(HLT="Y",ROW(HLT)),AL15)-1,COLUMN(StartDate)-1),"")} | AX15: {=IFERROR(OFFSET('[1](Fill In) SIAO'!$A$1,SMALL(IF(HLT="Y",ROW(HLT)),AL15)-1,COLUMN(EndDate)-1),"")} | AY15: {=IFERROR(OFFSET('[1](Fill In) SIAO'!$A$1,SMALL(IF(PANTES="Y",ROW(PANTES)),AL15)-1,COLUMN(StartDate)-1),"")} | AZ15: {=IFERROR(OFFSET('[1](Fill In) SIAO'!$A$1,SMALL(IF(PANTES="Y",ROW(PANTES)),AL15)-1,COLUMN(EndDate)-1),"")} | BA15: {=IFERROR(OFFSET('[1](Fill In) SIAO'!$A$1,SMALL(IF(Heli="Y",ROW(Heli)),AL15)-1,COLUMN(StartDate)-1),"")} | BB15: {=IFERROR(OFFSET('[1](Fill In) SIAO'!$A$1,SMALL(IF(Heli="Y",ROW(Heli)),AL15)-1,COLUMN(EndDate)-1),"")} | BC15: {=IFERROR(OFFSET('[1](Fill In) SIAO'!$A$1,SMALL(IF(MMR="Y",ROW(MMR)),AL15)-1,COLUMN(StartDate)-1),"")} | BD15: {=IFERROR(OFFSET('[1](Fill In) SIAO'!$A$1,SMALL(IF(MMR="Y",ROW(MMR)),AL15)-1,COLUMN(EndDate)-1),"")} | BE15: {=IFERROR(OFFSET('[1](Fill In) SIAO'!$A$1,SMALL(IF(POL="Y",ROW(POL)),AL15)-1,COLUMN(StartDate)-1),"")} | BF15: {=IFERROR(OFFSET('[1](Fill In) SIAO'!$A$1,SMALL(IF(POL="Y",ROW(POL)),AL15)-1,COLUMN(EndDate)-1),"")}
B16: Default | C16: =EOMONTH($A$1,-1) -> 46112 | D16: =C16+1 -> 46113 | E16: =D16+1 -> 46114 | F16: =E16+1 -> 46115 | G16: =F16+1 -> 46116 | H16: =G16+1 -> 46117 | I16: =H16+1 -> 46118 | J16: =I16+1 -> 46119 | K16: =J16+1 -> 46120 | ... AI16: =AH16+1 -> 46144 | AL16: 6 | AM16: {=IFERROR(OFFSET('[1](Fill In) SIAO'!$A$1,SMALL(IF(Signals="Y",ROW(Signals)),AL16)-1,COLUMN(Conducts)-1),"")} | AN16: {=IFERROR(OFFSET('[1](Fill In) SIAO'!$A$1,SMALL(IF(Signals="Y",ROW(Signals)),AL16)-1,COLUMN(StartDate)-1),"")} | AO16: {=IFERROR(OFFSET('[1](Fill In) SIAO'!$A$1,SMALL(IF(Signals="Y",ROW(Signals)),AL16)-1,COLUMN(EndDate)-1),"")} | AP16: {=IFERROR(OFFSET('[1](Fill In) SIAO'!$A$1,SMALL(IF(Optics="Y",ROW(Optics)),AL16)-1,COLUMN(Conducts)-1),"")} | AQ16: {=IFERROR(OFFSET('[1](Fill In) SIAO'!$A$1,SMALL(IF(Optics="Y",ROW(Optics)),AL16)-1,COLUMN(StartDate)-1),"")} | AR16: {=IFERROR(OFFSET('[1](Fill In) SIAO'!$A$1,SMALL(IF(Optics="Y",ROW(Optics)),AL16)-1,COLUMN(EndDate)-1),"")} | AS16: {=IFERROR(OFFSET('[1](Fill In) SIAO'!$A$1,SMALL(IF(ATMS="Y",ROW(ATMS)),AL16)-1,COLUMN(StartDate)-1),"")} | AT16: {=IFERROR(OFFSET('[1](Fill In) SIAO'!$A$1,SMALL(IF(ATMS="Y",ROW(ATMS)),AL16)-1,COLUMN(EndDate)-1),"")} | AU16: {=IFERROR(OFFSET('[1](Fill In) SIAO'!$A$1,SMALL(IF(UO="Y",ROW(UO)),AL16)-1,COLUMN(StartDate)-1),"")} | AV16: {=IFERROR(OFFSET('[1](Fill In) SIAO'!$A$1,SMALL(IF(UO="Y",ROW(UO)),AL16)-1,COLUMN(EndDate)-1),"")} | AW16: {=IFERROR(OFFSET('[1](Fill In) SIAO'!$A$1,SMALL(IF(HLT="Y",ROW(HLT)),AL16)-1,COLUMN(StartDate)-1),"")} | AX16: {=IFERROR(OFFSET('[1](Fill In) SIAO'!$A$1,SMALL(IF(HLT="Y",ROW(HLT)),AL16)-1,COLUMN(EndDate)-1),"")} | AY16: {=IFERROR(OFFSET('[1](Fill In) SIAO'!$A$1,SMALL(IF(PANTES="Y",ROW(PANTES)),AL16)-1,COLUMN(StartDate)-1),"")} | AZ16: {=IFERROR(OFFSET('[1](Fill In) SIAO'!$A$1,SMALL(IF(PANTES="Y",ROW(PANTES)),AL16)-1,COLUMN(EndDate)-1),"")} | BA16: {=IFERROR(OFFSET('[1](Fill In) SIAO'!$A$1,SMALL(IF(Heli="Y",ROW(Heli)),AL16)-1,COLUMN(StartDate)-1),"")} | BB16: {=IFERROR(OFFSET('[1](Fill In) SIAO'!$A$1,SMALL(IF(Heli="Y",ROW(Heli)),AL16)-1,COLUMN(EndDate)-1),"")} | BC16: {=IFERROR(OFFSET('[1](Fill In) SIAO'!$A$1,SMALL(IF(MMR="Y",ROW(MMR)),AL16)-1,COLUMN(StartDate)-1),"")} | BD16: {=IFERROR(OFFSET('[1](Fill In) SIAO'!$A$1,SMALL(IF(MMR="Y",ROW(MMR)),AL16)-1,COLUMN(EndDate)-1),"")} | BE16: {=IFERROR(OFFSET('[1](Fill In) SIAO'!$A$1,SMALL(IF(POL="Y",ROW(POL)),AL16)-1,COLUMN(StartDate)-1),"")} | BF16: {=IFERROR(OFFSET('[1](Fill In) SIAO'!$A$1,SMALL(IF(POL="Y",ROW(POL)),AL16)-1,COLUMN(EndDate)-1),"")}
